Workbook

Sheet Hilly Acres Farm Ltd. (2)
A1: Hilly Acres Farm Ltd. | F1: Week # | G1: =Inputs!C2 -> 1
A2: WEEKLY SUMMARY REPORT | F2: Week ending | G2: =Inputs!C3 -> 45662.25
N3: TOTAL
C4: Prod | D4: Marketing | E4: Housing | H4: TOTAL DZ | I4: NESTRUN | J4: TOTAL DZ | M4: TOTAL DZ | N4: MKTABLE
A5: BARN | C5: # | D5: Type | E5: Type | F5: Egg Type | G5: Colour | H5: RECEIVED | I5: DOZEN | J5: FOR GRADE | K5: REJECTS | L5: LOSS | M5: REJECTS/LOSS | N5: EGGS | O5: JUMBO | P5: EX LG | Q5: LARGE | R5: MEDIUM | S5: SMALL | T5: B GRADE | U5: CRACKS | V5: PEE WEE
A7: Theodore & John Eyking Sr. Barn 3 | C7: 7169 | D7: RE | E7: Conventional | F7: Regular | G7: White | H7: =IFERROR(M7+N7,"") -> 11039.028 | I7: 0 | J7: =IFERROR(H7-I7,"") -> 11039.028 | K7: =IFERROR(($E$26/($H$27+$H$28)*$H$27)*R28,"") -> 66.234165 | L7: =IFERROR(($E$26/($H$27+$H$28)*$H$27)*S28,"") -> 0 | M7: =IFERROR(K7+L7,"") -> 66.234165 | N7: =IFERROR(O7+P7+Q7+R7+S7+T7+U7+V7,"") -> 10972.793 | O7: =IFERROR(($E$26/($H$27+$H$28)*$H$27)*J28,"") -> 485.71721 | P7: =IFERROR(($E$26/($H$27+$H$28)*$H$27)*K28,"") -> 2892.2252 | Q7: =IFERROR(($E$26/($H$27+$H$28)*$H$27)*L28,"") -> 6634.4556 | R7: =IFERROR(($E$26/($H$27+$H$28)*$H$27)*M28,"") -> 883.1222 | S7: =IFERROR(($E$26/($H$27+$H$28)*$H$27)*N28,"") -> 11.039028 | T7: =IFERROR(($E$26/($H$27+$H$28)*$H$27)*O28,"") -> 0 | U7: =IFERROR(($E$26/($H$27+$H$28)*$H$27)*P28,"") -> 66.234165 | V7: =IFERROR(($E$26/($H$27+$H$28)*$H$27)*Q28,"") -> 0
A8: Theodore & John Eyking Sr. Barn 3 | C8: 7169 | D8: RE | E8: Conventional | F8: Regular | G8: Brown | H8: =IFERROR(M8+N8,"") -> 1065.9724 | I8: 0 | J8: =IFERROR(H8-I8,"") -> 1065.9724 | K8: =IFERROR(($E$26/($H$27+$H$28)*$H$28)*R28,"") -> 6.3958347 | L8: =IFERROR(($E$26/($H$27+$H$28)*$H$28)*S28,"") -> 0 | M8: =IFERROR(K8+L8,"") -> 6.3958347 | N8: =IFERROR(O8+P8+Q8+R8+S8+T8+U8+V8,"") -> 1059.5766 | O8: =IFERROR(($E$26/($H$27+$H$28)*$H$28)*J28,"") -> 46.902788 | P8: =IFERROR(($E$26/($H$27+$H$28)*$H$28)*K28,"") -> 279.28478 | Q8: =IFERROR(($E$26/($H$27+$H$28)*$H$28)*L28,"") -> 640.64944 | R8: =IFERROR(($E$26/($H$27+$H$28)*$H$28)*M28,"") -> 85.277796 | S8: =IFERROR(($E$26/($H$27+$H$28)*$H$28)*N28,"") -> 1.0659724 | T8: =IFERROR(($E$26/($H$27+$H$28)*$H$28)*O28,"") -> 0 | U8: =IFERROR(($E$26/($H$27+$H$28)*$H$28)*P28,"") -> 6.3958347 | V8: =IFERROR(($E$26/($H$27+$H$28)*$H$28)*Q28,"") -> 0
A10: Theodore & John Eyking Sr. Barn 6 | C10: 7169 | D10: RE | E10: Enriched | F10: Regular | G10: White | H10: =IFERROR(M10+N10,"") -> 23044.625 | I10: 0 | J10: =IFERROR(H10-I10,"") -> 23044.625 | K10: =IFERROR(($E$30/($H$31+$H$32)*$H$31)*R32,"") -> 345.825 | L10: =IFERROR(($E$30/($H$31+$H$32)*$H$31)*S32,"") -> 23.055 | M10: =IFERROR(K10+L10,"") -> 368.88 | N10: =IFERROR(O10+P10+Q10+R10+S10+T10+U10+V10,"") -> 22675.745 | O10: =IFERROR(($E$30/($H$31+$H$32)*$H$31)*J32,"") -> 1683.015 | P10: =IFERROR(($E$30/($H$31+$H$32)*$H$31)*K32,"") -> 7423.71 | Q10: =IFERROR(($E$30/($H$31+$H$32)*$H$31)*L32,"") -> 12334.425 | R10: =IFERROR(($E$30/($H$31+$H$32)*$H$31)*M32,"") -> 1152.75 | S10: =IFERROR(($E$30/($H$31+$H$32)*$H$31)*N32,"") -> 1.15275 | T10: =IFERROR(($E$30/($H$31+$H$32)*$H$31)*O32,"") -> 0 | U10: =IFERROR(($E$30/($H$31+$H$32)*$H$31)*P32,"") -> 69.165 | V10: =IFERROR(($E$30/($H$31+$H$32)*$H$31)*Q32,"") -> 11.5275
A11: Theodore & John Eyking Sr. Barn 6 | C11: 7169 | D11: RE | E11: Enriched | F11: Regular | G11: Brown | H11: =IFERROR(M11+N11,"") -> 0 | I11: 0 | J11: =IFERROR(H11-I11,"") -> 0 | K11: =IFERROR(($E$30/($H$31+$H$32)*$H$32)*R32,"") -> 0 | L11: =IFERROR(($E$30/($H$31+$H$32)*$H$32)*S32,"") -> 0 | M11: =IFERROR(K11+L11,"") -> 0 | N11: =IFERROR(O11+P11+Q11+R11+S11+T11+U11+V11,"") -> 0 | O11: =IFERROR(($E$30/($H$31+$H$32)*$H$32)*J32,"") -> 0 | P11: =IFERROR(($E$30/($H$31+$H$32)*$H$32)*K32,"") -> 0 | Q11: =IFERROR(($E$30/($H$31+$H$32)*$H$32)*L32,"") -> 0 | R11: =IFERROR(($E$30/($H$31+$H$32)*$H$32)*M32,"") -> 0 | S11: =IFERROR(($E$30/($H$31+$H$32)*$H$32)*N32,"") -> 0 | T11: =IFERROR(($E$30/($H$31+$H$32)*$H$32)*O32,"") -> 0 | U11: =IFERROR(($E$30/($H$31+$H$32)*$H$32)*P32,"") -> 0 | V11: =IFERROR(($E$30/($H$31+$H$32)*$H$32)*Q32,"") -> 0
A13: Chris Eyking New Barn 7 | C13: 7168 | D13: RE | E13: Enriched | F13: Regular | G13: White | H13: =IFERROR(M13+N13,"") -> 18926.604 | I13: 0 | J13: =IFERROR(H13-I13,"") -> 18926.604 | K13: =IFERROR(($E$34/($H$35+$H$36)*$H$35)*R36,"") -> 246.04585 | L13: =IFERROR(($E$34/($H$35+$H$36)*$H$35)*S36,"") -> 18.926604 | M13: =IFERROR(K13+L13,"") -> 264.97246 | N13: =IFERROR(O13+P13+Q13+R13+S13+T13+U13+V13,"") -> 18661.632 | O13: =IFERROR(($E$34/($H$35+$H$36)*$H$35)*J36,"") -> 340.67887 | P13: =IFERROR(($E$34/($H$35+$H$36)*$H$35)*K36,"") -> 3936.7337 | Q13: =IFERROR(($E$34/($H$35+$H$36)*$H$35)*L36,"") -> 12661.898 | R13: =IFERROR(($E$34/($H$35+$H$36)*$H$35)*M36,"") -> 1684.4678 | S13: =IFERROR(($E$34/($H$35+$H$36)*$H$35)*N36,"") -> 18.926604 | T13: =IFERROR(($E$34/($H$35+$H$36)*$H$35)*O36,"") -> 0 | U13: =IFERROR(($E$34/($H$35+$H$36)*$H$35)*P36,"") -> 18.926604 | V13: =IFERROR(($E$34/($H$35+$H$36)*$H$35)*Q36,"") -> 0
A14: Chris Eyking New Barn 7 | C14: 7168 | D14: RE | E14: Enriched | F14: Regular | G14: Brown | H14: =IFERROR(M14+N14,"") -> 2148.3959 | I14: 0 | J14: =IFERROR(H14-I14,"") -> 2148.3959 | K14: =IFERROR(($E$34/($H$35+$H$36)*$H$36)*R36,"") -> 27.929146 | L14: =IFERROR(($E$34/($H$35+$H$36)*$H$36)*S36,"") -> 2.1483959 | M14: =IFERROR(K14+L14,"") -> 30.077542 | N14: =IFERROR(O14+P14+Q14+R14+S14+T14+U14+V14,"") -> 2118.3183 | O14: =IFERROR(($E$34/($H$35+$H$36)*$H$36)*J36,"") -> 38.671125 | P14: =IFERROR(($E$34/($H$35+$H$36)*$H$36)*K36,"") -> 446.86634 | Q14: =IFERROR(($E$34/($H$35+$H$36)*$H$36)*L36,"") -> 1437.2768 | R14: =IFERROR(($E$34/($H$35+$H$36)*$H$36)*M36,"") -> 191.20723 | S14: =IFERROR(($E$34/($H$35+$H$36)*$H$36)*N36,"") -> 2.1483959 | T14: =IFERROR(($E$34/($H$35+$H$36)*$H$36)*O36,"") -> 0 | U14: =IFERROR(($E$34/($H$35+$H$36)*$H$36)*P36,"") -> 2.1483959 | V14: =IFERROR(($E$34/($H$35+$H$36)*$H$36)*Q36,"") -> 0
A16: Chris Eyking Barn 11 | C16: 7168 | D16: RE | E16: Enriched | F16: Regular | G16: White | H16: =IFERROR(M16+N16,"") -> 11415 | I16: 0 | J16: =IFERROR(H16-I16,"") -> 11415 | K16: =IFERROR(($E$38/($H$39)*$H$39)*R40,"") -> 159.81 | L16: =IFERROR(($E$38/($H$39)*$H$39)*S40,"") -> 22.83 | M16: =IFERROR(K16+L16,"") -> 182.64 | N16: =IFERROR(O16+P16+Q16+R16+S16+T16+U16+V16,"") -> 11232.36 | O16: =IFERROR(($E$38/($H$39)*$H$39)*J40,"") -> 616.41 | P16: =IFERROR(($E$38/($H$39)*$H$39)*K40,"") -> 3276.105 | Q16: =IFERROR(($E$38/($H$39)*$H$39)*L40,"") -> 6369.57 | R16: =IFERROR(($E$38/($H$39)*$H$39)*M40,"") -> 913.2 | S16: =IFERROR(($E$38/($H$39)*$H$39)*N40,"") -> 11.415 | T16: =IFERROR(($E$38/($H$39)*$H$39)*O40,"") -> 0 | U16: =IFERROR(($E$38/($H$39)*$H$39)*P40,"") -> 45.66 | V16: =IFERROR(($E$38/($H$39)*$H$39)*Q40,"") -> 0
A19: Totals | H19: =SUM(H7:H18) -> 67639.625 | I19: =SUM(I7:I18) -> 0 | J19: =SUM(J7:J18) -> 67639.625 | K19: =SUM(K7:K18) -> 852.24 | L19: =SUM(L7:L18) -> 66.96 | M19: =SUM(M7:M18) -> 919.2 | N19: =SUM(N7:N18) -> 66720.425 | O19: =SUM(O7:O18) -> 3211.395 | ... V19: =SUM(V7:V18) -> 11.5275
N21: =M19+N19 -> 67639.625
A22: **Email this to Lorraine Ryan, IP Office, email address: lorraine@nsegg.ca
H24: BIRD INVENTORY FOR WEEK | J24: JUMBO | K24: EX LG | L24: LARGE | M24: MEDIUM | N24: SMALL | O24: B GRADE | P24: CRACKS | Q24: PEE WEE | R24: REJECTS | S24: LOSS | T24: TOTAL DOZEN
A26: Barn 3 total dozen production for the week | E26: =Inputs!J29+Inputs!K29 -> 12105
A27: Theodore & John Eyking Sr. Barn 3 | C27: 7169 | D27: RE | E27: Conventional | F27: Regular | G27: White | H27: ='Bird Inventory'!H3 -> 20256 | J27: =$E$26*J28 -> 532.62 | K27: =$E$26*K28 -> 3171.51 | L27: =$E$26*L28 -> 7275.105 | M27: =$E$26*M28 -> 968.4 | N27: =$E$26*N28 -> 12.105 | O27: =$E$26*O28 -> 0 | P27: =$E$26*P28 -> 72.63 | Q27: =$E$26*Q28 -> 0 | ... S27: =$E$26*S28 -> 0 | T27: =SUM(J27:S27) -> 12105
A28: Theodore & John Eyking Sr. Barn 3 | C28: 7169 | D28: RE | E28: Conventional | F28: Regular | G28: Brown | H28: ='Bird Inventory'!H4 -> 1956 | J28: =Inputs!B37 -> 0.044 | K28: =Inputs!B38 -> 0.262 | L28: =Inputs!B39 -> 0.601 | M28: =Inputs!B40 -> 0.08 | N28: =Inputs!B41 -> 0.001 | O28: 0 | P28: =Inputs!B49 -> 0.006 | Q28: =Inputs!B42 -> 0 | R28: =Inputs!B50+Inputs!B48 -> 0.006 | S28: =Inputs!B47 -> 0 | T28: =SUM(J28:S28) -> 1
A30: Barn 6 total dozen production for the week | E30: =Inputs!J30 -> 23055
A31: Theodore & John Eyking Sr. Barn 6 | C31: 7169 | D31: RE | E31: Enriched | F31: Regular | G31: White | H31: ='Bird Inventory'!H6 -> 39064 | J31: =$E30*J32 -> 1683.015 | K31: =$E30*K32 -> 7423.71 | L31: =$E30*L32 -> 12334.425 | M31: =$E30*M32 -> 1152.75 | N31: =$E30*N32 -> 1.15275 | O31: =$E30*O32 -> 0 | P31: =$E30*P32 -> 69.165 | Q31: =$E30*Q32 -> 11.5275 | ... S31: =$E30*S32 -> 23.055 | T31: =SUM(J31:S31) -> 23044.625
J32: =Inputs!C37 -> 0.073 | K32: =Inputs!C38 -> 0.322 | L32: =Inputs!C39 -> 0.535 | M32: =Inputs!C40 -> 0.05 | N32: =Inputs!C41 -> 5e-05 | O32: 0 | P32: =Inputs!C49 -> 0.003 | Q32: =Inputs!C42 -> 0.0005 | R32: =Inputs!C48+Inputs!C50 -> 0.015 | S32: =Inputs!C47 -> 0.001 | T32: =SUM(J32:S32) -> 0.99955
A34: Barn 7 total dozen production for the week | E34: =Inputs!J31+Inputs!K31 -> 21075
A35: Chris Eyking Barn 7 | C35: 7168 | D35: RE | E35: Enriched | F35: Regular | G35: White | H35: ='Bird Inventory'!H8 -> 34710 | J35: =$E34*J36 -> 379.35 | K35: =$E34*K36 -> 4383.6 | L35: =$E34*L36 -> 14099.175 | M35: =$E34*M36 -> 1875.675 | N35: =$E34*N36 -> 21.075 | O35: =$E34*O36 -> 0 | P35: =$E34*P36 -> 21.075 | Q35: =$E34*Q36 -> 0 | ... S35: =$E34*S36 -> 21.075 | T35: =SUM(J35:S35) -> 21075
A36: Chris Eyking Barn 7 | C36: 7168 | D36: RE | E36: Enriched | F36: Regular | G36: Brown | H36: ='Bird Inventory'!H9 -> 3940 | J36: =Inputs!D37 -> 0.018 | K36: =Inputs!D38 -> 0.208 | L36: =Inputs!D39 -> 0.669 | M36: =Inputs!D40 -> 0.089 | N36: =Inputs!D41 -> 0.001 | O36: 0 | P36: =Inputs!D49 -> 0.001 | Q36: =Inputs!D42 -> 0 | R36: =Inputs!D48+Inputs!D50 -> 0.013 | S36: =Inputs!D47 -> 0.001 | T36: =SUM(J36:S36) -> 1
A38: Barn 11 total dozen production for the week | E38: =Inputs!J32 -> 11415
A39: Chris Eyking Barn 11 | C39: 7168 | D39: RE | E39: Enriched | F39: Regular | G39: White | H39: ='Bird Inventory'!H11 -> 18990 | J39: =$E38*J40 -> 616.41 | K39: =$E38*K40 -> 3276.105 | L39: =$E38*L40 -> 6369.57 | M39: =$E38*M40 -> 913.2 | N39: =$E38*N40 -> 11.415 | O39: =$E38*O40 -> 0 | P39: =$E38*P40 -> 45.66 | Q39: =$E38*Q40 -> 0 | ... S39: =$E38*S40 -> 22.83 | T39: =SUM(J39:S39) -> 11415
J40: =Inputs!E37 -> 0.054 | K40: =Inputs!E38 -> 0.287 | L40: =Inputs!E39 -> 0.558 | M40: =Inputs!E40 -> 0.08 | N40: =Inputs!E41 -> 0.001 | O40: 0 | P40: =Inputs!E49 -> 0.004 | Q40: =Inputs!E42 -> 0 | R40: =Inputs!E48+Inputs!E50 -> 0.014 | S40: =Inputs!E47 -> 0.002 | T40: =SUM(J40:S40) -> 1

Sheet Hilly Acres Farm Ltd.
A1: Hilly Acres Farm Ltd. | F1: Week # | G1: =Inputs!C2 -> 1
A2: WEEKLY SUMMARY REPORT | F2: Week ending | G2: =Inputs!C3 -> 45662.25
N3: TOTAL
C4: Prod | D4: Marketing | E4: Housing | H4: TOTAL DZ | I4: NESTRUN | J4: TOTAL DZ | M4: TOTAL DZ | N4: MKTABLE
A5: BARN | C5: # | D5: Type | E5: Type | F5: Egg Type | G5: Colour | H5: RECEIVED | I5: DOZEN | J5: FOR GRADE | K5: REJECTS | L5: LOSS | M5: REJECTS/LOSS | N5: EGGS | O5: JUMBO | P5: EX LG | Q5: LARGE | R5: MEDIUM | S5: SMALL | T5: B GRADE | U5: CRACKS | V5: PEE WEE
A7: Theodore & John Eyking Sr. Barn 3 | C7: 7169 | D7: RE | E7: Conventional | F7: Regular | G7: White | H7: =IFERROR(M7+N7,"") -> 11039.028 | I7: 0 | J7: =IFERROR(H7-I7,"") -> 11039.028 | K7: =IFERROR(($E$26/($H$27+$H$28)*$H$27)*R28,"") -> 66.234165 | L7: =IFERROR(($E$26/($H$27+$H$28)*$H$27)*S28,"") -> 0 | M7: =IFERROR(K7+L7,"") -> 66.234165 | N7: =IFERROR(O7+P7+Q7+R7+S7+T7+U7+V7,"") -> 10972.793 | O7: =IFERROR(($E$26/($H$27+$H$28)*$H$27)*J28,"") -> 485.71721 | P7: =IFERROR(($E$26/($H$27+$H$28)*$H$27)*K28,"") -> 2892.2252 | Q7: =IFERROR(($E$26/($H$27+$H$28)*$H$27)*L28,"") -> 6634.4556 | R7: =IFERROR(($E$26/($H$27+$H$28)*$H$27)*M28,"") -> 883.1222 | S7: =IFERROR(($E$26/($H$27+$H$28)*$H$27)*N28,"") -> 11.039028 | T7: =IFERROR(($E$26/($H$27+$H$28)*$H$27)*O28,"") -> 0 | U7: =IFERROR(($E$26/($H$27+$H$28)*$H$27)*P28,"") -> 66.234165 | V7: =IFERROR(($E$26/($H$27+$H$28)*$H$27)*Q28,"") -> 0
A8: Theodore & John Eyking Sr. Barn 3 | C8: 7169 | D8: RE | E8: Conventional | F8: Regular | G8: Brown | H8: =IFERROR(M8+N8,"") -> 1065.9724 | I8: 0 | J8: =IFERROR(H8-I8,"") -> 1065.9724 | K8: =IFERROR(($E$26/($H$27+$H$28)*$H$28)*R28,"") -> 6.3958347 | L8: =IFERROR(($E$26/($H$27+$H$28)*$H$28)*S28,"") -> 0 | M8: =IFERROR(K8+L8,"") -> 6.3958347 | N8: =IFERROR(O8+P8+Q8+R8+S8+T8+U8+V8,"") -> 1059.5766 | O8: =IFERROR(($E$26/($H$27+$H$28)*$H$28)*J28,"") -> 46.902788 | P8: =IFERROR(($E$26/($H$27+$H$28)*$H$28)*K28,"") -> 279.28478 | Q8: =IFERROR(($E$26/($H$27+$H$28)*$H$28)*L28,"") -> 640.64944 | R8: =IFERROR(($E$26/($H$27+$H$28)*$H$28)*M28,"") -> 85.277796 | S8: =IFERROR(($E$26/($H$27+$H$28)*$H$28)*N28,"") -> 1.0659724 | T8: =IFERROR(($E$26/($H$27+$H$28)*$H$28)*O28,"") -> 0 | U8: =IFERROR(($E$26/($H$27+$H$28)*$H$28)*P28,"") -> 6.3958347 | V8: =IFERROR(($E$26/($H$27+$H$28)*$H$28)*Q28,"") -> 0
A10: Theodore & John Eyking Sr. Barn 6 | C10: 7169 | D10: RE | E10: Enriched | F10: Regular | G10: White | H10: =IFERROR(M10+N10,"") -> 23044.625 | I10: 0 | J10: =IFERROR(H10-I10,"") -> 23044.625 | K10: =IFERROR(($E$30/($H$31+$H$32)*$H$31)*R32,"") -> 345.825 | L10: =IFERROR(($E$30/($H$31+$H$32)*$H$31)*S32,"") -> 23.055 | M10: =IFERROR(K10+L10,"") -> 368.88 | N10: =IFERROR(O10+P10+Q10+R10+S10+T10+U10+V10,"") -> 22675.745 | O10: =IFERROR(($E$30/($H$31+$H$32)*$H$31)*J32,"") -> 1683.015 | P10: =IFERROR(($E$30/($H$31+$H$32)*$H$31)*K32,"") -> 7423.71 | Q10: =IFERROR(($E$30/($H$31+$H$32)*$H$31)*L32,"") -> 12334.425 | R10: =IFERROR(($E$30/($H$31+$H$32)*$H$31)*M32,"") -> 1152.75 | S10: =IFERROR(($E$30/($H$31+$H$32)*$H$31)*N32,"") -> 1.15275 | T10: =IFERROR(($E$30/($H$31+$H$32)*$H$31)*O32,"") -> 0 | U10: =IFERROR(($E$30/($H$31+$H$32)*$H$31)*P32,"") -> 69.165 | V10: =IFERROR(($E$30/($H$31+$H$32)*$H$31)*Q32,"") -> 11.5275
A11: Theodore & John Eyking Sr. Barn 6 | C11: 7169 | D11: RE | E11: Enriched | F11: Regular | G11: Brown | H11: =IFERROR(M11+N11,"") -> 0 | I11: 0 | J11: =IFERROR(H11-I11,"") -> 0 | K11: =IFERROR(($E$30/($H$31+$H$32)*$H$32)*R32,"") -> 0 | L11: =IFERROR(($E$30/($H$31+$H$32)*$H$32)*S32,"") -> 0 | M11: =IFERROR(K11+L11,"") -> 0 | N11: =IFERROR(O11+P11+Q11+R11+S11+T11+U11+V11,"") -> 0 | O11: =IFERROR(($E$30/($H$31+$H$32)*$H$32)*J32,"") -> 0 | P11: =IFERROR(($E$30/($H$31+$H$32)*$H$32)*K32,"") -> 0 | Q11: =IFERROR(($E$30/($H$31+$H$32)*$H$32)*L32,"") -> 0 | R11: =IFERROR(($E$30/($H$31+$H$32)*$H$32)*M32,"") -> 0 | S11: =IFERROR(($E$30/($H$31+$H$32)*$H$32)*N32,"") -> 0 | T11: =IFERROR(($E$30/($H$31+$H$32)*$H$32)*O32,"") -> 0 | U11: =IFERROR(($E$30/($H$31+$H$32)*$H$32)*P32,"") -> 0 | V11: =IFERROR(($E$30/($H$31+$H$32)*$H$32)*Q32,"") -> 0
A13: Chris Eyking New Barn 7 | C13: 7168 | D13: RE | E13: Enriched | F13: Regular | G13: White | H13: =IFERROR(M13+N13,"") -> 18926.604 | I13: 0 | J13: =IFERROR(H13-I13,"") -> 18926.604 | K13: =IFERROR(($E$34/($H$35+$H$36)*$H$35)*R36,"") -> 246.04585 | L13: =IFERROR(($E$34/($H$35+$H$36)*$H$35)*S36,"") -> 18.926604 | M13: =IFERROR(K13+L13,"") -> 264.97246 | N13: =IFERROR(O13+P13+Q13+R13+S13+T13+U13+V13,"") -> 18661.632 | O13: =IFERROR(($E$34/($H$35+$H$36)*$H$35)*J36,"") -> 340.67887 | P13: =IFERROR(($E$34/($H$35+$H$36)*$H$35)*K36,"") -> 3936.7337 | Q13: =IFERROR(($E$34/($H$35+$H$36)*$H$35)*L36,"") -> 12661.898 | R13: =IFERROR(($E$34/($H$35+$H$36)*$H$35)*M36,"") -> 1684.4678 | S13: =IFERROR(($E$34/($H$35+$H$36)*$H$35)*N36,"") -> 18.926604 | T13: =IFERROR(($E$34/($H$35+$H$36)*$H$35)*O36,"") -> 0 | U13: =IFERROR(($E$34/($H$35+$H$36)*$H$35)*P36,"") -> 18.926604 | V13: =IFERROR(($E$34/($H$35+$H$36)*$H$35)*Q36,"") -> 0
A14: Chris Eyking New Barn 7 | C14: 7168 | D14: RE | E14: Enriched | F14: Regular | G14: Brown | H14: =IFERROR(M14+N14,"") -> 2148.3959 | I14: 0 | J14: =IFERROR(H14-I14,"") -> 2148.3959 | K14: =IFERROR(($E$34/($H$35+$H$36)*$H$36)*R36,"") -> 27.929146 | L14: =IFERROR(($E$34/($H$35+$H$36)*$H$36)*S36,"") -> 2.1483959 | M14: =IFERROR(K14+L14,"") -> 30.077542 | N14: =IFERROR(O14+P14+Q14+R14+S14+T14+U14+V14,"") -> 2118.3183 | O14: =IFERROR(($E$34/($H$35+$H$36)*$H$36)*J36,"") -> 38.671125 | P14: =IFERROR(($E$34/($H$35+$H$36)*$H$36)*K36,"") -> 446.86634 | Q14: =IFERROR(($E$34/($H$35+$H$36)*$H$36)*L36,"") -> 1437.2768 | R14: =IFERROR(($E$34/($H$35+$H$36)*$H$36)*M36,"") -> 191.20723 | S14: =IFERROR(($E$34/($H$35+$H$36)*$H$36)*N36,"") -> 2.1483959 | T14: =IFERROR(($E$34/($H$35+$H$36)*$H$36)*O36,"") -> 0 | U14: =IFERROR(($E$34/($H$35+$H$36)*$H$36)*P36,"") -> 2.1483959 | V14: =IFERROR(($E$34/($H$35+$H$36)*$H$36)*Q36,"") -> 0
A16: Chris Eyking Barn 11 | C16: 7168 | D16: RE | E16: Enriched | F16: Regular | G16: White | H16: =IFERROR(M16+N16,"") -> 11415 | I16: 0 | J16: =IFERROR(H16-I16,"") -> 11415 | K16: =IFERROR(($E$38/($H$39)*$H$39)*R40,"") -> 159.81 | L16: =IFERROR(($E$38/($H$39)*$H$39)*S40,"") -> 22.83 | M16: =IFERROR(K16+L16,"") -> 182.64 | N16: =IFERROR(O16+P16+Q16+R16+S16+T16+U16+V16,"") -> 11232.36 | O16: =IFERROR(($E$38/($H$39)*$H$39)*J40,"") -> 616.41 | P16: =IFERROR(($E$38/($H$39)*$H$39)*K40,"") -> 3276.105 | Q16: =IFERROR(($E$38/($H$39)*$H$39)*L40,"") -> 6369.57 | R16: =IFERROR(($E$38/($H$39)*$H$39)*M40,"") -> 913.2 | S16: =IFERROR(($E$38/($H$39)*$H$39)*N40,"") -> 11.415 | T16: =IFERROR(($E$38/($H$39)*$H$39)*O40,"") -> 0 | U16: =IFERROR(($E$38/($H$39)*$H$39)*P40,"") -> 45.66 | V16: =IFERROR(($E$38/($H$39)*$H$39)*Q40,"") -> 0
A19: Totals | H19: =SUM(H7:H18) -> 67639.625 | I19: =SUM(I7:I18) -> 0 | J19: =SUM(J7:J18) -> 67639.625 | K19: =SUM(K7:K18) -> 852.24 | L19: =SUM(L7:L18) -> 66.96 | M19: =SUM(M7:M18) -> 919.2 | N19: =SUM(N7:N18) -> 66720.425 | O19: =SUM(O7:O18) -> 3211.395 | ... V19: =SUM(V7:V18) -> 11.5275
N21: =M19+N19 -> 67639.625
A22: **Email this to Lorraine Ryan, IP Office, email address: lorraine@nsegg.ca
H24: BIRD INVENTORY FOR WEEK | J24: JUMBO | K24: EX LG | L24: LARGE | M24: MEDIUM | N24: SMALL | O24: B GRADE | P24: CRACKS | Q24: PEE WEE | R24: REJECTS | S24: LOSS | T24: TOTAL DOZEN
A26: Barn 3 total dozen production for the week | E26: =Inputs!J29+Inputs!K29 -> 12105
A27: Theodore & John Eyking Sr. Barn 3 | C27: 7169 | D27: RE | E27: Conventional | F27: Regular | G27: White | H27: ='Bird Inventory'!H3 -> 20256 | J27: =$E$26*J28 -> 532.62 | K27: =$E$26*K28 -> 3171.51 | L27: =$E$26*L28 -> 7275.105 | M27: =$E$26*M28 -> 968.4 | N27: =$E$26*N28 -> 12.105 | O27: =$E$26*O28 -> 0 | P27: =$E$26*P28 -> 72.63 | Q27: =$E$26*Q28 -> 0 | ... S27: =$E$26*S28 -> 0 | T27: =SUM(J27:S27) -> 12105
A28: Theodore & John Eyking Sr. Barn 3 | C28: 7169 | D28: RE | E28: Conventional | F28: Regular | G28: Brown | H28: ='Bird Inventory'!H4 -> 1956 | J28: =Inputs!B37 -> 0.044 | K28: =Inputs!B38 -> 0.262 | L28: =Inputs!B39 -> 0.601 | M28: =Inputs!B40 -> 0.08 | N28: =Inputs!B41 -> 0.001 | O28: 0 | P28: =Inputs!B49 -> 0.006 | Q28: =Inputs!B42 -> 0 | R28: =Inputs!B50+Inputs!B48 -> 0.006 | S28: =Inputs!B47 -> 0 | T28: =SUM(J28:S28) -> 1
A30: Barn 6 total dozen production for the week | E30: =Inputs!J30 -> 23055
A31: Theodore & John Eyking Sr. Barn 6 | C31: 7169 | D31: RE | E31: Enriched | F31: Regular | G31: White | H31: ='Bird Inventory'!H6 -> 39064 | J31: =$E30*J32 -> 1683.015 | K31: =$E30*K32 -> 7423.71 | L31: =$E30*L32 -> 12334.425 | M31: =$E30*M32 -> 1152.75 | N31: =$E30*N32 -> 1.15275 | O31: =$E30*O32 -> 0 | P31: =$E30*P32 -> 69.165 | Q31: =$E30*Q32 -> 11.5275 | ... S31: =$E30*S32 -> 23.055 | T31: =SUM(J31:S31) -> 23044.625
J32: =Inputs!C37 -> 0.073 | K32: =Inputs!C38 -> 0.322 | L32: =Inputs!C39 -> 0.535 | M32: =Inputs!C40 -> 0.05 | N32: =Inputs!C41 -> 5e-05 | O32: 0 | P32: =Inputs!C49 -> 0.003 | Q32: =Inputs!C42 -> 0.0005 | R32: =Inputs!C48+Inputs!C50 -> 0.015 | S32: =Inputs!C47 -> 0.001 | T32: =SUM(J32:S32) -> 0.99955
A34: Barn 7 total dozen production for the week | E34: =Inputs!J31+Inputs!K31 -> 21075
A35: Chris Eyking Barn 7 | C35: 7168 | D35: RE | E35: Enriched | F35: Regular | G35: White | H35: ='Bird Inventory'!H8 -> 34710 | J35: =$E34*J36 -> 379.35 | K35: =$E34*K36 -> 4383.6 | L35: =$E34*L36 -> 14099.175 | M35: =$E34*M36 -> 1875.675 | N35: =$E34*N36 -> 21.075 | O35: =$E34*O36 -> 0 | P35: =$E34*P36 -> 21.075 | Q35: =$E34*Q36 -> 0 | ... S35: =$E34*S36 -> 21.075 | T35: =SUM(J35:S35) -> 21075
A36: Chris Eyking Barn 7 | C36: 7168 | D36: RE | E36: Enriched | F36: Regular | G36: Brown | H36: ='Bird Inventory'!H9 -> 3940 | J36: =Inputs!D37 -> 0.018 | K36: =Inputs!D38 -> 0.208 | L36: =Inputs!D39 -> 0.669 | M36: =Inputs!D40 -> 0.089 | N36: =Inputs!D41 -> 0.001 | O36: 0 | P36: =Inputs!D49 -> 0.001 | Q36: =Inputs!D42 -> 0 | R36: =Inputs!D48+Inputs!D50 -> 0.013 | S36: =Inputs!D47 -> 0.001 | T36: =SUM(J36:S36) -> 1
A38: Barn 11 total dozen production for the week | E38: =Inputs!J32 -> 11415
A39: Chris Eyking Barn 11 | C39: 7168 | D39: RE | E39: Enriched | F39: Regular | G39: White | H39: ='Bird Inventory'!H11 -> 18990 | J39: =$E38*J40 -> 616.41 | K39: =$E38*K40 -> 3276.105 | L39: =$E38*L40 -> 6369.57 | M39: =$E38*M40 -> 913.2 | N39: =$E38*N40 -> 11.415 | O39: =$E38*O40 -> 0 | P39: =$E38*P40 -> 45.66 | Q39: =$E38*Q40 -> 0 | ... S39: =$E38*S40 -> 22.83 | T39: =SUM(J39:S39) -> 11415
J40: =Inputs!E37 -> 0.054 | K40: =Inputs!E38 -> 0.287 | L40: =Inputs!E39 -> 0.558 | M40: =Inputs!E40 -> 0.08 | N40: =Inputs!E41 -> 0.001 | O40: 0 | P40: =Inputs!E49 -> 0.004 | Q40: =Inputs!E42 -> 0 | R40: =Inputs!E48+Inputs!E50 -> 0.014 | S40: =Inputs!E47 -> 0.002 | T40: =SUM(J40:S40) -> 1

Sheet Declaration Summary
A1: NS IP DECLARATION
A3: DATE: | B3: =Inputs!C3 -> 45662.25
A5: TO: | B5: Egg Farmers of Nova Scotia | F5: PREPARED BY
B6: Email: Lorraine @nsegg.ca | F6: =Inputs!B5 -> Pamela Penney
A7: FROM: | B7: Hilly Acres Farm Ltd.
A9: RE: | B9: SURPLUS EGGS WEEK # | E9: =Inputs!C2 -> 1
B12: Boxes | C12: Dozens
A13: Nest Run | B13: =C13/15 -> 1860 | C13: ='Grade out Information'!X26 -> 27900
A15: Graded X Large White | B15: =C15/15 -> 0 | C15: ='Grade out Information'!C11 -> 0
A16: Graded X Large Brown | B16: =C16/15 -> 0 | C16: ='Grade out Information'!C12 -> 0
A18: Graded Large White | B18: =C18/15 -> 0 | C18: ='Grade out Information'!D11 -> 0
A19: Graded Large Brown | B19: =C19/15 -> 0 | C19: ='Grade out Information'!D12 -> 0
A21: Graded Medium White | B21: =C21/15 -> 60 | C21: ='Grade out Information'!E11 -> 900
A22: Graded Medium Brown | B22: =C22/15 -> 0 | C22: ='Grade out Information'!E12 -> 0
A24: Graded Small White | B24: =C24/15 -> 0 | C24: ='Grade out Information'!F11 -> 0
A25: Graded Small Brown | B25: =C25/15 -> 0 | C25: ='Grade out Information'!F12 -> 0
A27: TOTAL: | B27: =SUM(B13:B26) -> 1920 | C27: =SUM(C13:C26) -> 28800
B29: Left | C29: Left | D29: Left | E29: Declared | F29: Already | G29: Total
A30: BOXES | B30: From WK # | C30: From WK # | D30: From WK # | E30: WK # | F30: Shipped wk # | G30: on
G31: Hand
A32: Nest Run | E32: 0 | G32: =SUM(B32:E32)-F32 -> 0
A34: Graded X Large- White | E34: =('Grade out Information'!C11)/15 -> 0 | G34: =SUM(B34:E34)-F34 -> 0
A35: Graded X Large- Brown | E35: =('Grade out Information'!C12)/15 -> 0 | G35: =SUM(B35:E35)-F35 -> 0
A36: Graded Large- White | E36: =('Grade out Information'!D11)/15 -> 0 | G36: =SUM(B36:E36)-F36 -> 0
A37: Graded Large- Brown | E37: =('Grade out Information'!D12)/15 -> 0 | G37: =SUM(B37:E37)-F37 -> 0
A38: Graded Medium- White | E38: 0 | G38: =SUM(B38:E38)-F38 -> 0
A39: Graded Medium- Brown | E39: =('Grade out Information'!E12)/15 -> 0 | G39: =SUM(B39:E39)-F39 -> 0
A40: Graded Small- White | E40: =('Grade out Information'!F11)/15 -> 0 | G40: =SUM(B40:E40)-F40 -> 0
A41: Graded Small- Brown | E41: =('Grade out Information'!F12)/15 -> 0 | G41: =SUM(B41:E41)-F41 -> 0
A42: TOTAL: | B42: =SUM(B32:B41) -> 0 | C42: =SUM(C32:C41) -> 0 | D42: =SUM(D32:D41) -> 0 | E42: =SUM(E32:E41) -> 0 | F42: =SUM(F32:F41) -> 0 | G42: =SUM(G32:G41) -> 0

Sheet Grade out Information
A1: IP Breakdown to determine percentages and weights for the various IP Shippers
A3: Egg Farmers of Nova Scotia
A4: Hilly Acres Farm Ltd.
A7: Week | B7: Location | C7: Graded IP Dozens | G7: Graded Total | H7: Graded Total | I7: % of total | J7: Nest Run | K7: J/XL | M7: L | O7: M | Q7: S | S7: PW | U7: B | W7: UG | X7: NR Total | Y7: Total | Z7: NR Total | AA7: % of total | AB7: Grand Total | AC7: Grand Total | AD7: % of total
A8: =Inputs!C2 -> 1 | C8: XL | D8: L | E8: M | F8: S | G8: Dozens | H8: Boxes | I8: Graded | J8: J/XL | K8: % | L8: L | M8: % | N8: M | O8: % | P8: S | Q8: % | R8: PW | S8: % | T8: B | U8: % | V8: UG | W8: % | X8: Dozens | Y8: % | Z8: Boxes | AA8: NR | AB8: Dozens | AC8: Boxes | AD8: IP
B9: GRADED IP INFORMATION
B11: Graded - White | E11: =Inputs!I41*15 -> 900 | G11: =SUM(C11:F11) -> 900 | H11: =G11/15 -> 60
B12: Graded - Brown | G12: =SUM(C12:F12) -> 0 | H12: =G12/15 -> 0
B14: NR GRADE OUT INFORMATION
B15: Theodore & John Eyking Sr. Barn 3 - White | I15: =J15+L15+N15+P15+R15+T15+V15 -> 3600 | J15: =X15*K15 -> 1101.6 | K15: =Inputs!B36 -> 0.306 | L15: =X15*M15 -> 2163.6 | M15: =Inputs!B39 -> 0.601 | N15: =X15*O15 -> 288 | O15: =Inputs!B40 -> 0.08 | P15: =X15*Q15 -> 3.6 | Q15: =Inputs!B41 -> 0.001 | R15: =X15*S15 -> 0 | S15: =Inputs!B42 -> 0 | T15: =X15*U15 -> 0 | U15: 0 | V15: =X15*W15 -> 43.2 | W15: =Inputs!B43 -> 0.012 | X15: =Z15*15 -> 3600 | Y15: =K15+M15+O15+Q15+S15+U15+W15 -> 1 | Z15: =Inputs!I35 -> 240
B16: Theodore & John Eyking Sr. Barn 3- Brown | I16: =J16+L16+N16+P16+R16+T16+V16 -> 0 | J16: =X16*K16 -> 0 | K16: =K15 -> 0.306 | L16: =X16*M16 -> 0 | M16: =M15 -> 0.601 | N16: =X16*O16 -> 0 | O16: =O15 -> 0.08 | P16: =X16*Q16 -> 0 | Q16: =Q15 -> 0.001 | R16: =X16*S16 -> 0 | S16: =S15 -> 0 | T16: =X16*U16 -> 0 | U16: 0 | V16: =X16*W16 -> 0 | W16: =W15 -> 0.012 | X16: =Z16*15 -> 0 | Y16: =K16+M16+O16+Q16+S16+U16+W16 -> 1 | Z16: =Inputs!I36 -> 0
I17: =J17+L17+N17+P17+R17+T17+V17 -> 0
B18: Theodore & John Eyking Sr. Barn 6 - White | I18: =J18+L18+N18+P18+R18+T18+V18 -> 10795.14 | J18: =X18*K18 -> 4266 | K18: =Inputs!C36 -> 0.395 | L18: =X18*M18 -> 5778 | M18: =Inputs!C39 -> 0.535 | N18: =X18*O18 -> 540 | O18: =Inputs!C40 -> 0.05 | P18: =X18*Q18 -> 0.54 | Q18: =Inputs!C41 -> 5e-05 | R18: =X18*S18 -> 5.4 | S18: =Inputs!C42 -> 0.0005 | T18: =X18*U18 -> 0 | U18: 0 | V18: =X18*W18 -> 205.2 | W18: =Inputs!C43 -> 0.019 | X18: =Z18*15 -> 10800 | Y18: =K18+M18+O18+Q18+S18+U18+W18 -> 0.99955 | Z18: =Inputs!I37 -> 720
I19: =J19+L19+N19+P19+R19+T19+V19 -> 0
B20: Chris Eyking Barn 7 - White | I20: =J20+L20+N20+P20+R20+T20+V20 -> 8100 | J20: =X20*K20 -> 1830.6 | K20: =Inputs!D36 -> 0.226 | L20: =X20*M20 -> 5418.9 | M20: =Inputs!D39 -> 0.669 | N20: =X20*O20 -> 720.9 | O20: =Inputs!D40 -> 0.089 | P20: =X20*Q20 -> 8.1 | Q20: =Inputs!D41 -> 0.001 | R20: =X20*S20 -> 0 | S20: =Inputs!D42 -> 0 | T20: =X20*U20 -> 0 | U20: 0 | V20: =X20*W20 -> 121.5 | W20: =Inputs!D43 -> 0.015 | X20: =Z20*15 -> 8100 | Y20: =K20+M20+O20+Q20+S20+U20+W20 -> 1 | Z20: =Inputs!I38 -> 540
B21: Chris Eyking Barn 7 - Brown | I21: =J21+L21+N21+P21+R21+T21+V21 -> 1800 | J21: =X21*K21 -> 406.8 | K21: =K20 -> 0.226 | L21: =X21*M21 -> 1204.2 | M21: =M20 -> 0.669 | N21: =X21*O21 -> 160.2 | O21: =O20 -> 0.089 | P21: =X21*Q21 -> 1.8 | Q21: =Q20 -> 0.001 | R21: =X21*S21 -> 0 | S21: =S20 -> 0 | T21: =X21*U21 -> 0 | U21: 0 | V21: =X21*W21 -> 27 | W21: =W20 -> 0.015 | X21: =Z21*15 -> 1800 | Y21: =K21+M21+O21+Q21+S21+U21+W21 -> 1 | Z21: =Inputs!I39 -> 120
I22: =J22+L22+N22+P22+R22+T22+V22 -> 0
B23: Chris Eyking Barn 11 - White | I23: =J23+L23+N23+P23+R23+T23+V23 -> 3600 | J23: =X23*K23 -> 1227.6 | K23: =Inputs!E36 -> 0.341 | L23: =X23*M23 -> 2008.8 | M23: =Inputs!E39 -> 0.558 | N23: =X23*O23 -> 288 | O23: =Inputs!E40 -> 0.08 | P23: =X23*Q23 -> 3.6 | Q23: =Inputs!E41 -> 0.001 | R23: =X23*S23 -> 0 | S23: =Inputs!E42 -> 0 | T23: =X23*U23 -> 0 | U23: 0 | V23: =X23*W23 -> 72 | W23: =Inputs!E43 -> 0.02 | X23: =Z23*15 -> 3600 | Y23: =K23+M23+O23+Q23+S23+U23+W23 -> 1 | Z23: =Inputs!I40 -> 240
B26: Totals | C26: =SUM(C11:C25) -> 0 | D26: =SUM(D11:D25) -> 0 | E26: =SUM(E11:E25) -> 900 | F26: =SUM(F11:F25) -> 0 | G26: =G11+G12 -> 900 | H26: =SUM(H11+H12) -> 60 | J26: =SUM(J15:J25) -> 8832.6 | L26: =SUM(L15:L25) -> 16573.5 | N26: =SUM(N15:N25) -> 1997.1 | P26: =SUM(P15:P25) -> 17.64 | R26: =SUM(R15:R25) -> 5.4 | T26: =SUM(T15:T25) -> 0 | V26: =SUM(V15:V25) -> 468.9 | X26: =SUM(X15:X25) -> 27900 | Z26: =SUM(Z15:Z25) -> 1860 | AA26: =IF(Z33=0,0,Z33/(H33+Z33)) -> 0 | AB26: =G26+X26 -> 28800 | AC26: =H26+Z26 -> 1920 | AD26: =I26+AA26 -> 0
A30: J/XL | B30: =J26 -> 8832.6
A31: L | B31: =L26 -> 16573.5
A32: M | B32: =N26 -> 1997.1
A33: S | B33: =P26 -> 17.64
A34: PW | B34: =R26 -> 5.4
A35: B | B35: =T26 -> 0
A36: UG | B36: =V26 -> 468.9
A38: TOTAL | B38: =SUM(B30:B36) -> 27895.14

Sheet Bird Inventory
A1: Bird Inventory
A3: Theodore & John Eyking Sr. Barn 3 | C3: 7168 | D3: RE | E3: Conventional | F3: Regular | G3: White | H3: 20256
A4: Theodore & John Eyking Sr. Barn 3 | C4: 7168 | D4: RE | E4: Conventional | F4: Regular | G4: Brown | H4: 1956
A6: Theodore & John Eyking Sr. Barn 6 | C6: 7169 | D6: RE | E6: Enriched | F6: Regular | G6: White | H6: 39064
A8: Chris Eyking New Barn 7 | C8: 7168 | D8: RE | E8: Enriched | F8: Regular | G8: White | H8: 34710
A9: Chris Eyking New Barn 7 | C9: 7168 | D9: RE | E9: Enriched | F9: Regular | G9: Brown | H9: 3940
A11: Chris Eyking Barn 11 | C11: 7168 | D11: RE | E11: Enriched | F11: Regular | G11: White | H11: 18990

Sheet Pallet Information
A1: NO# | B1: WK | C1: TAG# | D1: BARN | E1: QUAN | F1: NR | G1: GRADED IP | H1: PACK | I1: NET | J1: Packaging | K1: GROSS | L1: WT | M1: IP# | N1: SHIP DATE | O1: CLR | P1: AGE
A2: Sample for Grading Station
B3: 5 | C3: 123456 | D3: 7168-C3 | E3: 60 | F3: NR | H3: OLD | I3: =K3-192 -> 1408 | J3: =IF(H3="NEW",203, IF(H3="OLD",192,0)) -> 192 | K3: 1600 | L3: =I3/E3 -> 23.466667 | M3: 789456 | N3: 43663 | O3: White | P3: 50
B4: 5 | C4: 123457 | D4: 7169-E6 | E4: 60 | G4: X L | H4: OLD | I4: =K4-J4 -> 1458 | J4: =IF(H4="NEW",203, IF(H4="OLD",192,0)) -> 192 | K4: 1650 | M4: 789456 | N4: 43663 | O4: White | P4: 30
B5: 5 | C5: 123458 | D5: 7168-C10 | E5: 60 | G5: LARGE | H5: NEW | I5: =K5-J5 -> 1497 | J5: =IF(H5="NEW",203, IF(H5="OLD",192,0)) -> 203 | K5: 1700 | M5: 789456 | N5: 43663 | O5: Brown
A7: 1 | B7: =Inputs!C$2 -> 1 | C7: 389924 | D7: 7169-E6 | E7: 60 | F7: NR | H7: NEW | I7: =IF(K7>0,K7-J7,"NA") -> 1509 | J7: =IF(H7="NEW",203, IF(H7="OLD",192,0)) -> 203 | K7: 1712 | L7: =IF(K7>0,I7/E7,"NA") -> 25.15 | M7: 938822 | N7: Jan 3/25 | O7: White | P7: =IF(D7=Inputs!F$2,Inputs!I$2,IF(D7=Inputs!F$3,Inputs!I$3,IF(D7=Inputs!F$4,Inputs!I$4,IF(D7=Inputs!F$5,Inputs!I$5,"NA")))) -> 38.892857
A8: 2 | B8: =Inputs!C$2 -> 1 | C8: 389925 | D8: 7169-C3 | E8: 60 | F8: NR | H8: NEW | I8: =IF(K8>0,K8-J8,"NA") -> 1495 | J8: =IF(H8="NEW",203, IF(H8="OLD",192,0)) -> 203 | K8: 1698 | L8: =IF(K8>0,I8/E8,"NA") -> 24.916667 | M8: 938822 | N8: Jan 3/25 | O8: White | P8: =IF(D8=Inputs!F$2,Inputs!I$2,IF(D8=Inputs!F$3,Inputs!I$3,IF(D8=Inputs!F$4,Inputs!I$4,IF(D8=Inputs!F$5,Inputs!I$5,"NA")))) -> 56.892857
A9: 3 | B9: =Inputs!C$2 -> 1 | C9: 389926 | D9: 7169-C3 | E9: 60 | F9: NR | H9: NEW | I9: =IF(K9>0,K9-J9,"NA") -> 1471 | J9: =IF(H9="NEW",203, IF(H9="OLD",192,0)) -> 203 | K9: 1674 | L9: =IF(K9>0,I9/E9,"NA") -> 24.516667 | M9: 938822 | N9: Jan 3/25 | O9: White | P9: =IF(D9=Inputs!F$2,Inputs!I$2,IF(D9=Inputs!F$3,Inputs!I$3,IF(D9=Inputs!F$4,Inputs!I$4,IF(D9=Inputs!F$5,Inputs!I$5,"NA")))) -> 56.892857
A10: 4 | B10: =Inputs!C$2 -> 1 | C10: 389927 | D10: 7168-E7 | E10: 60 | F10: NR | H10: NEW | I10: =IF(K10>0,K10-J10,"NA") -> 1519 | J10: =IF(H10="NEW",203, IF(H10="OLD",192,0)) -> 203 | K10: 1722 | L10: =IF(K10>0,I10/E10,"NA") -> 25.316667 | M10: 938822 | N10: Jan 3/25 | O10: White | P10: =IF(D10=Inputs!F$2,Inputs!I$2,IF(D10=Inputs!F$3,Inputs!I$3,IF(D10=Inputs!F$4,Inputs!I$4,IF(D10=Inputs!F$5,Inputs!I$5,"NA")))) -> 64.892857
A11: 5 | B11: =Inputs!C$2 -> 1 | C11: 389928 | D11: 7168-E7 | E11: 60 | F11: NR | H11: NEW | I11: =IF(K11>0,K11-J11,"NA") -> 1529 | J11: =IF(H11="NEW",203, IF(H11="OLD",192,0)) -> 203 | K11: 1732 | L11: =IF(K11>0,I11/E11,"NA") -> 25.483333 | M11: 938822 | N11: Jan 3/25 | O11: White | P11: =IF(D11=Inputs!F$2,Inputs!I$2,IF(D11=Inputs!F$3,Inputs!I$3,IF(D11=Inputs!F$4,Inputs!I$4,IF(D11=Inputs!F$5,Inputs!I$5,"NA")))) -> 64.892857
A12: 6 | B12: =Inputs!C$2 -> 1 | C12: 389929 | D12: 7168-E7 | E12: 60 | F12: NR | H12: NEW | I12: =IF(K12>0,K12-J12,"NA") -> 1515 | J12: =IF(H12="NEW",203, IF(H12="OLD",192,0)) -> 203 | K12: 1718 | L12: =IF(K12>0,I12/E12,"NA") -> 25.25 | M12: 938822 | N12: Jan 3/25 | O12: White | P12: =IF(D12=Inputs!F$2,Inputs!I$2,IF(D12=Inputs!F$3,Inputs!I$3,IF(D12=Inputs!F$4,Inputs!I$4,IF(D12=Inputs!F$5,Inputs!I$5,"NA")))) -> 64.892857
A13: 7 | B13: =Inputs!C$2 -> 1 | C13: 389930 | D13: 7168-E11 | E13: 60 | F13: NR | H13: NEW | I13: =IF(K13>0,K13-J13,"NA") -> 1471 | J13: =IF(H13="NEW",203, IF(H13="OLD",192,0)) -> 203 | K13: 1674 | L13: =IF(K13>0,I13/E13,"NA") -> 24.516667 | M13: 938822 | N13: Jan 3/25 | O13: White | P13: =IF(D13=Inputs!F$2,Inputs!I$2,IF(D13=Inputs!F$3,Inputs!I$3,IF(D13=Inputs!F$4,Inputs!I$4,IF(D13=Inputs!F$5,Inputs!I$5,"NA")))) -> 30.464286
A14: 8 | B14: =Inputs!C$2 -> 1 | C14: 389931 | D14: 7168-E11 | E14: 60 | F14: NR | H14: NEW | I14: =IF(K14>0,K14-J14,"NA") -> 1485 | J14: =IF(H14="NEW",203, IF(H14="OLD",192,0)) -> 203 | K14: 1688 | L14: =IF(K14>0,I14/E14,"NA") -> 24.75 | M14: 938822 | N14: Jan 3/25 | O14: White | P14: =IF(D14=Inputs!F$2,Inputs!I$2,IF(D14=Inputs!F$3,Inputs!I$3,IF(D14=Inputs!F$4,Inputs!I$4,IF(D14=Inputs!F$5,Inputs!I$5,"NA")))) -> 30.464286
A15: 9 | B15: =Inputs!C$2 -> 1 | C15: 389932 | D15: 7169-E6 | E15: 60 | F15: NR | H15: NEW | I15: =IF(K15>0,K15-J15,"NA") -> 1517 | J15: =IF(H15="NEW",203, IF(H15="OLD",192,0)) -> 203 | K15: 1720 | L15: =IF(K15>0,I15/E15,"NA") -> 25.283333 | M15: 938822 | N15: Jan 3/25 | O15: White | P15: =IF(D15=Inputs!F$2,Inputs!I$2,IF(D15=Inputs!F$3,Inputs!I$3,IF(D15=Inputs!F$4,Inputs!I$4,IF(D15=Inputs!F$5,Inputs!I$5,"NA")))) -> 38.892857
A16: 10 | B16: =Inputs!C$2 -> 1 | C16: 389933 | D16: 7169-E6 | E16: 60 | F16: NR | H16: NEW | I16: =IF(K16>0,K16-J16,"NA") -> 1511 | J16: =IF(H16="NEW",203, IF(H16="OLD",192,0)) -> 203 | K16: 1714 | L16: =IF(K16>0,I16/E16,"NA") -> 25.183333 | M16: 938822 | N16: Jan 3/25 | O16: White | P16: =IF(D16=Inputs!F$2,Inputs!I$2,IF(D16=Inputs!F$3,Inputs!I$3,IF(D16=Inputs!F$4,Inputs!I$4,IF(D16=Inputs!F$5,Inputs!I$5,"NA")))) -> 38.892857
A17: 11 | B17: =Inputs!C$2 -> 1 | C17: 389934 | D17: 7169-E6 | E17: 60 | F17: NR | H17: NEW | I17: =IF(K17>0,K17-J17,"NA") -> 1507 | J17: =IF(H17="NEW",203, IF(H17="OLD",192,0)) -> 203 | K17: 1710 | L17: =IF(K17>0,I17/E17,"NA") -> 25.116667 | M17: 938822 | N17: Jan 3/25 | O17: White | P17: =IF(D17=Inputs!F$2,Inputs!I$2,IF(D17=Inputs!F$3,Inputs!I$3,IF(D17=Inputs!F$4,Inputs!I$4,IF(D17=Inputs!F$5,Inputs!I$5,"NA")))) -> 38.892857
A18: 12 | B18: =Inputs!C$2 -> 1 | C18: 389935 | D18: Graded IP | E18: 60 | G18: MED | H18: NEW | I18: =IF(K18>0,K18-J18,"NA") -> NA | J18: =IF(H18="NEW",203, IF(H18="OLD",192,0)) -> 203 | L18: =IF(K18>0,I18/E18,"NA") -> NA | M18: 938822 | N18: Jan 3/25 | O18: White | P18: =IF(D18=Inputs!F$2,Inputs!I$2,IF(D18=Inputs!F$3,Inputs!I$3,IF(D18=Inputs!F$4,Inputs!I$4,IF(D18=Inputs!F$5,Inputs!I$5,"NA")))) -> NA
A19: 13 | B19: =Inputs!C$2 -> 1 | C19: 389936 | D19: 7168-E7 | E19: 60 | F19: NR | H19: NEW | I19: =IF(K19>0,K19-J19,"NA") -> 1479 | J19: =IF(H19="NEW",203, IF(H19="OLD",192,0)) -> 203 | K19: 1682 | L19: =IF(K19>0,I19/E19,"NA") -> 24.65 | M19: 938822 | N19: Jan 3/25 | O19: Brown | P19: =IF(D19=Inputs!F$2,Inputs!I$2,IF(D19=Inputs!F$3,Inputs!I$3,IF(D19=Inputs!F$4,Inputs!I$4,IF(D19=Inputs!F$5,Inputs!I$5,"NA")))) -> 64.892857
A20: 14 | B20: =Inputs!C$2 -> 1 | C20: 389937 | D20: 7169-E6 | E20: 60 | F20: NR | H20: NEW | I20: =IF(K20>0,K20-J20,"NA") -> 1511 | J20: =IF(H20="NEW",203, IF(H20="OLD",192,0)) -> 203 | K20: 1714 | L20: =IF(K20>0,I20/E20,"NA") -> 25.183333 | M20: 938822 | N20: Jan 3/25 | O20: White | P20: =IF(D20=Inputs!F$2,Inputs!I$2,IF(D20=Inputs!F$3,Inputs!I$3,IF(D20=Inputs!F$4,Inputs!I$4,IF(D20=Inputs!F$5,Inputs!I$5,"NA")))) -> 38.892857
A21: 15 | B21: =Inputs!C$2 -> 1 | C21: 389938 | D21: 7169-E6 | E21: 60 | F21: NR | H21: NEW | I21: =IF(K21>0,K21-J21,"NA") -> 1505 | J21: =IF(H21="NEW",203, IF(H21="OLD",192,0)) -> 203 | K21: 1708 | L21: =IF(K21>0,I21/E21,"NA") -> 25.083333 | M21: 938822 | N21: Jan 3/25 | O21: White | P21: =IF(D21=Inputs!F$2,Inputs!I$2,IF(D21=Inputs!F$3,Inputs!I$3,IF(D21=Inputs!F$4,Inputs!I$4,IF(D21=Inputs!F$5,Inputs!I$5,"NA")))) -> 38.892857
A22: 16 | B22: =Inputs!C$2 -> 1 | C22: 389939 | D22: 7169-E6 | E22: 60 | F22: NR | H22: NEW | I22: =IF(K22>0,K22-J22,"NA") -> 1515 | J22: =IF(H22="NEW",203, IF(H22="OLD",192,0)) -> 203 | K22: 1718 | L22: =IF(K22>0,I22/E22,"NA") -> 25.25 | M22: 938822 | N22: Jan 3/25 | O22: White | P22: =IF(D22=Inputs!F$2,Inputs!I$2,IF(D22=Inputs!F$3,Inputs!I$3,IF(D22=Inputs!F$4,Inputs!I$4,IF(D22=Inputs!F$5,Inputs!I$5,"NA")))) -> 38.892857
A23: 17 | B23: =Inputs!C$2 -> 1 | C23: 389940 | D23: 7169-E6 | E23: 60 | F23: NR | H23: NEW | I23: =IF(K23>0,K23-J23,"NA") -> 1507 | J23: =IF(H23="NEW",203, IF(H23="OLD",192,0)) -> 203 | K23: 1710 | L23: =IF(K23>0,I23/E23,"NA") -> 25.116667 | M23: 938822 | N23: Jan 3/25 | O23: White | P23: =IF(D23=Inputs!F$2,Inputs!I$2,IF(D23=Inputs!F$3,Inputs!I$3,IF(D23=Inputs!F$4,Inputs!I$4,IF(D23=Inputs!F$5,Inputs!I$5,"NA")))) -> 38.892857
A24: 18 | B24: =Inputs!C$2 -> 1 | C24: 389941 | D24: 7168-E7 | E24: 60 | F24: NR | H24: NEW | I24: =IF(K24>0,K24-J24,"NA") -> 1513 | J24: =IF(H24="NEW",203, IF(H24="OLD",192,0)) -> 203 | K24: 1716 | L24: =IF(K24>0,I24/E24,"NA") -> 25.216667 | M24: 938822 | N24: Jan 3/25 | O24: White | P24: =IF(D24=Inputs!F$2,Inputs!I$2,IF(D24=Inputs!F$3,Inputs!I$3,IF(D24=Inputs!F$4,Inputs!I$4,IF(D24=Inputs!F$5,Inputs!I$5,"NA")))) -> 64.892857
A25: 19 | B25: =Inputs!C$2 -> 1 | C25: 389942 | D25: 7168-E7 | E25: 60 | F25: NR | H25: NEW | I25: =IF(K25>0,K25-J25,"NA") -> 1505 | J25: =IF(H25="NEW",203, IF(H25="OLD",192,0)) -> 203 | K25: 1708 | L25: =IF(K25>0,I25/E25,"NA") -> 25.083333 | M25: 938822 | N25: Jan 3/25 | O25: White | P25: =IF(D25=Inputs!F$2,Inputs!I$2,IF(D25=Inputs!F$3,Inputs!I$3,IF(D25=Inputs!F$4,Inputs!I$4,IF(D25=Inputs!F$5,Inputs!I$5,"NA")))) -> 64.892857
A26: 20 | B26: =Inputs!C$2 -> 1 | C26: 389943 | D26: 7168-E7 | E26: 60 | F26: NR | H26: NEW | I26: =IF(K26>0,K26-J26,"NA") -> 1501 | J26: =IF(H26="NEW",203, IF(H26="OLD",192,0)) -> 203 | K26: 1704 | L26: =IF(K26>0,I26/E26,"NA") -> 25.016667 | M26: 938822 | N26: Jan 3/25 | O26: White | P26: =IF(D26=Inputs!F$2,Inputs!I$2,IF(D26=Inputs!F$3,Inputs!I$3,IF(D26=Inputs!F$4,Inputs!I$4,IF(D26=Inputs!F$5,Inputs!I$5,"NA")))) -> 64.892857
A27: 21 | B27: =Inputs!C$2 -> 1 | C27: 389944 | D27: 7168-E7 | E27: 60 | F27: NR | H27: NEW | I27: =IF(K27>0,K27-J27,"NA") -> 1491 | J27: =IF(H27="NEW",203, IF(H27="OLD",192,0)) -> 203 | K27: 1694 | L27: =IF(K27>0,I27/E27,"NA") -> 24.85 | M27: 938822 | N27: Jan 3/25 | O27: White | P27: =IF(D27=Inputs!F$2,Inputs!I$2,IF(D27=Inputs!F$3,Inputs!I$3,IF(D27=Inputs!F$4,Inputs!I$4,IF(D27=Inputs!F$5,Inputs!I$5,"NA")))) -> 64.892857
A28: 22 | B28: =Inputs!C$2 -> 1 | C28: 389945 | D28: 7169-C3 | E28: 60 | F28: NR | H28: NEW | I28: =IF(K28>0,K28-J28,"NA") -> 1503 | J28: =IF(H28="NEW",203, IF(H28="OLD",192,0)) -> 203 | K28: 1706 | L28: =IF(K28>0,I28/E28,"NA") -> 25.05 | M28: 938822 | N28: Jan 3/25 | O28: White | P28: =IF(D28=Inputs!F$2,Inputs!I$2,IF(D28=Inputs!F$3,Inputs!I$3,IF(D28=Inputs!F$4,Inputs!I$4,IF(D28=Inputs!F$5,Inputs!I$5,"NA")))) -> 56.892857
A29: 23 | B29: =Inputs!C$2 -> 1 | C29: 389946 | D29: 7168-E11 | E29: 60 | F29: NR | H29: NEW | I29: =IF(K29>0,K29-J29,"NA") -> 1469 | J29: =IF(H29="NEW",203, IF(H29="OLD",192,0)) -> 203 | K29: 1672 | L29: =IF(K29>0,I29/E29,"NA") -> 24.483333 | M29: 938822 | N29: Jan 3/25 | O29: White | P29: =IF(D29=Inputs!F$2,Inputs!I$2,IF(D29=Inputs!F$3,Inputs!I$3,IF(D29=Inputs!F$4,Inputs!I$4,IF(D29=Inputs!F$5,Inputs!I$5,"NA")))) -> 30.464286
A30: 24 | B30: =Inputs!C$2 -> 1 | C30: 389947 | D30: 7168-E11 | E30: 60 | F30: NR | H30: NEW | I30: =IF(K30>0,K30-J30,"NA") -> 1483 | J30: =IF(H30="NEW",203, IF(H30="OLD",192,0)) -> 203 | K30: 1686 | L30: =IF(K30>0,I30/E30,"NA") -> 24.716667 | M30: 938822 | N30: Jan 3/25 | O30: White | P30: =IF(D30=Inputs!F$2,Inputs!I$2,IF(D30=Inputs!F$3,Inputs!I$3,IF(D30=Inputs!F$4,Inputs!I$4,IF(D30=Inputs!F$5,Inputs!I$5,"NA")))) -> 30.464286
... A35: 29 | B35: =Inputs!C$2 -> 1 | C35: 389952 | D35: 7169-E6 | E35: 60 | F35: NR | H35: NEW | I35: =IF(K35>0,K35-J35,"NA") -> 1549 | J35: =IF(H35="NEW",203, IF(H35="OLD",192,0)) -> 203 | K35: 1752 | L35: =IF(K35>0,I35/E35,"NA") -> 25.816667 | M35: 938822 | N35: Jan 3/25 | O35: White | P35: =IF(D35=Inputs!F$2,Inputs!I$2,IF(D35=Inputs!F$3,Inputs!I$3,IF(D35=Inputs!F$4,Inputs!I$4,IF(D35=Inputs!F$5,Inputs!I$5,"NA")))) -> 38.892857
A36: 30 | B36: =Inputs!C$2 -> 1 | C36: 389953 | D36: 7169-E6 | F36: NR | H36: NEW | I36: =IF(K36>0,K36-J36,"NA") -> 1541 | J36: =IF(H36="NEW",203, IF(H36="OLD",192,0)) -> 203 | K36: 1744 | L36: =IF(K36>0,I36/E36,"NA") -> #DIV/0! | M36: 938822 | N36: Jan 3/25 | O36: White | P36: =IF(D36=Inputs!F$2,Inputs!I$2,IF(D36=Inputs!F$3,Inputs!I$3,IF(D36=Inputs!F$4,Inputs!I$4,IF(D36=Inputs!F$5,Inputs!I$5,"NA")))) -> 38.892857
A37: 31 | B37: =Inputs!C$2 -> 1 | C37: 389954 | D37: 7168-E7 | F37: NR | H37: NEW | I37: =IF(K37>0,K37-J37,"NA") -> 1521 | J37: =IF(H37="NEW",203, IF(H37="OLD",192,0)) -> 203 | K37: 1724 | L37: =IF(K37>0,I37/E37,"NA") -> #DIV/0! | M37: 938822 | N37: Jan 3/25 | O37: White | P37: =IF(D37=Inputs!F$2,Inputs!I$2,IF(D37=Inputs!F$3,Inputs!I$3,IF(D37=Inputs!F$4,Inputs!I$4,IF(D37=Inputs!F$5,Inputs!I$5,"NA")))) -> 64.892857
A38: 32 | B38: =Inputs!C$2 -> 1 | C38: 389955 | D38: 7168-E7 | F38: NR | H38: NEW | I38: =IF(K38>0,K38-J38,"NA") -> 1513 | J38: =IF(H38="NEW",203, IF(H38="OLD",192,0)) -> 203 | K38: 1716 | L38: =IF(K38>0,I38/E38,"NA") -> #DIV/0! | M38: 938822 | N38: Jan 3/25 | O38: White | P38: =IF(D38=Inputs!F$2,Inputs!I$2,IF(D38=Inputs!F$3,Inputs!I$3,IF(D38=Inputs!F$4,Inputs!I$4,IF(D38=Inputs!F$5,Inputs!I$5,"NA")))) -> 64.892857
A39: 33 | B39: =Inputs!C$2 -> 1 | I39: =IF(K39>0,K39-J39,"NA") -> NA | J39: =IF(H39="NEW",203, IF(H39="OLD",192,0)) -> 0 | L39: =IF(K39>0,I39/E39,"NA") -> NA | P39: =IF(D39=Inputs!F$2,Inputs!I$2,IF(D39=Inputs!F$3,Inputs!I$3,IF(D39=Inputs!F$4,Inputs!I$4,IF(D39=Inputs!F$5,Inputs!I$5,"NA")))) -> NA
A40: 34 | B40: =Inputs!C$2 -> 1 | I40: =IF(K40>0,K40-J40,"NA") -> NA | J40: =IF(H40="NEW",203, IF(H40="OLD",192,0)) -> 0 | L40: =IF(K40>0,I40/E40,"NA") -> NA | P40: =IF(D40=Inputs!F$2,Inputs!I$2,IF(D40=Inputs!F$3,Inputs!I$3,IF(D40=Inputs!F$4,Inputs!I$4,IF(D40=Inputs!F$5,Inputs!I$5,"NA")))) -> NA
A41: 35 | B41: =Inputs!C$2 -> 1 | I41: =IF(K41>0,K41-J41,"NA") -> NA | J41: =IF(H41="NEW",203, IF(H41="OLD",192,0)) -> 0 | L41: =IF(K41>0,I41/E41,"NA") -> NA | P41: =IF(D41=Inputs!F$2,Inputs!I$2,IF(D41=Inputs!F$3,Inputs!I$3,IF(D41=Inputs!F$4,Inputs!I$4,IF(D41=Inputs!F$5,Inputs!I$5,"NA")))) -> NA
A42: 36 | B42: =Inputs!C$2 -> 1 | I42: =IF(K42>0,K42-J42,"NA") -> NA | J42: =IF(H42="NEW",203, IF(H42="OLD",192,0)) -> 0 | L42: =IF(K42>0,I42/E42,"NA") -> NA | P42: =IF(D42=Inputs!F$2,Inputs!I$2,IF(D42=Inputs!F$3,Inputs!I$3,IF(D42=Inputs!F$4,Inputs!I$4,IF(D42=Inputs!F$5,Inputs!I$5,"NA")))) -> NA
A43: 37 | B43: =Inputs!C$2 -> 1 | I43: =IF(K43>0,K43-J43,"NA") -> NA | J43: =IF(H43="NEW",203, IF(H43="OLD",192,0)) -> 0 | L43: =IF(K43>0,I43/E43,"NA") -> NA | P43: =IF(D43=Inputs!F$2,Inputs!I$2,IF(D43=Inputs!F$3,Inputs!I$3,IF(D43=Inputs!F$4,Inputs!I$4,IF(D43=Inputs!F$5,Inputs!I$5,"NA")))) -> NA
A44: 38 | B44: =Inputs!C$2 -> 1 | I44: =IF(K44>0,K44-J44,"NA") -> NA | J44: =IF(H44="NEW",203, IF(H44="OLD",192,0)) -> 0 | L44: =IF(K44>0,I44/E44,"NA") -> NA | P44: =IF(D44=Inputs!F$2,Inputs!I$2,IF(D44=Inputs!F$3,Inputs!I$3,IF(D44=Inputs!F$4,Inputs!I$4,IF(D44=Inputs!F$5,Inputs!I$5,"NA")))) -> NA
A45: 39 | B45: =Inputs!C$2 -> 1 | I45: =IF(K45>0,K45-J45,"NA") -> NA | J45: =IF(H45="NEW",203, IF(H45="OLD",192,0)) -> 0 | L45: =IF(K45>0,I45/E45,"NA") -> NA | P45: =IF(D45=Inputs!F$2,Inputs!I$2,IF(D45=Inputs!F$3,Inputs!I$3,IF(D45=Inputs!F$4,Inputs!I$4,IF(D45=Inputs!F$5,Inputs!I$5,"NA")))) -> NA
...

Sheet Inputs
B1: Year | C1: 2025 | G1: Hatch Date | I1: Age | J1: Wks lay | K1: Pallets
B2: Week | C2: 1 | F2: 7169-C3 | G2: 45264 | I2: =(C$3-G2)/7 -> 56.892857 | J2: =I2-19 -> 37.892857 | K2: NEW | L2: 203
B3: Week Ending | C3: =C2*7+(C1-1900)*365.25-1 -> 45662.25 | F3: 7169-E6 | G3: 45390 | I3: =(C$3-G3)/7 -> 38.892857 | J3: =I3-19 -> 19.892857 | K3: OLD | L3: 192
F4: 7168-E7 | G4: 45208 | I4: =(C$3-G4)/7 -> 64.892857 | J4: =I4-19 -> 45.892857
A5: Prepared by | B5: Pamela Penney | F5: 7168-E11 | G5: 45449 | I5: =(C$3-G5)/7 -> 30.464286 | J5: =I5-19 -> 11.464286
A7: PRODUCTION (# of stacks)
A8: SUNDAY | E8: MONDAY
A9: Barn | B9: White | C9: Brown | E9: Barn | F9: White | G9: Brown
A10: 3 | B10: 90 | C10: 10 | E10: 3 | F10: 110 | G10: 13
A11: 6 | B11: 216 | E11: 6 | F11: 225
A12: 7 | B12: 170 | C12: 18 | E12: 7 | F12: 194 | G12: 22
A13: 11 | B13: 108 | E13: 11 | F13: 108
A14: TUESDAY | E14: WEDNESDAY
A15: Barn | B15: White | C15: Brown | E15: Barn | F15: White | G15: Brown
A16: 3 | B16: 108 | C16: 11 | E16: 3 | F16: 98 | G16: 10
A17: 6 | B17: 222 | E17: 6 | F17: 210
A18: 7 | B18: 192 | C18: 21 | E18: 7 | F18: 178 | G18: 21
A19: 11 | B19: 102 | E19: 11 | F19: 108
A21: THURSDAY | E21: FRIDAY
A22: Barn | B22: White | C22: Brown | E22: Barn | F22: White | G22: Brown
A23: 3 | B23: 110 | C23: 11 | E23: 3 | F23: 107 | G23: 11
A24: 6 | B24: 222 | E24: 6 | F24: 222
A25: 7 | B25: 176 | C25: 22 | E25: 7 | F25: 180 | G25: 21
A26: 11 | B26: 108 | E26: 11 | F26: 117
A27: SATURDAY | E27: TOTAL (stacks) | I27: TOTAL (dozens)
A28: Barn | B28: White | C28: Brown | E28: Barn | F28: White | G28: Brown | I28: Barn | J28: White | K28: Brown
A29: 3 | B29: 107 | C29: 11 | E29: 3 | F29: =B10+F10+B16+F16+B23+F23+B29 -> 730 | G29: =C10+G10+C16+G16+C23+G23+C29 -> 77 | I29: 3 | J29: =F29*15 -> 10950 | K29: =G29*15 -> 1155
A30: 6 | B30: 220 | E30: 6 | F30: =B11+F11+B17+F17+B24+F24+B30 -> 1537 | G30: =C11+G11+C17+G17+C24+G24+C30 -> 0 | I30: 6 | J30: =F30*15 -> 23055 | K30: =G30*15 -> 0
A31: 7 | B31: 170 | C31: 20 | E31: 7 | F31: =B12+F12+B18+F18+B25+F25+B31 -> 1260 | G31: =C12+G12+C18+G18+C25+G25+C31 -> 145 | I31: 7 | J31: =F31*15 -> 18900 | K31: =G31*15 -> 2175
A32: 11 | B32: 110 | E32: 11 | F32: =B13+F13+B19+F19+B26+F26+B32 -> 761 | G32: =C13+G13+C19+G19+C26+G26+C32 -> 0 | I32: 11 | J32: =F32*15 -> 11415 | K32: =G32*180/12 -> 0
A34: GRADE OUT | G34: NEST RUN TOTALS (Boxes/Stacks)
B35: Barn 10 | C35: Barn 6 | D35: Barn 7 | E35: Barn 11 | G35: Barn 3 White | I35: 240
A36: J/XL | B36: =B37+B38 -> 0.306 | C36: =C37+C38 -> 0.395 | D36: =D37+D38 -> 0.226 | E36: =E37+E38 -> 0.341 | G36: Barn 3 Brown | I36: 0
A37: Jumbo | B37: 0.044 | C37: 0.073 | D37: 0.018 | E37: 0.054 | G37: Barn 6 White | I37: 720
A38: Xlarge | B38: 0.262 | C38: 0.322 | D38: 0.208 | E38: 0.287 | G38: Barn 7 White | I38: 540
A39: Large | B39: 0.601 | C39: 0.535 | D39: 0.669 | E39: 0.558 | G39: Barn 7 Brown | I39: 120
A40: Medium | B40: 0.08 | C40: 0.05 | D40: 0.089 | E40: 0.08 | G40: Barn 11 White | I40: 240
A41: Small | B41: 0.001 | C41: 5e-05 | D41: 0.001 | E41: 0.001 | G41: Medium | I41: 60
A42: Peewee | B42: 0 | C42: 0.0005 | D42: 0 | E42: 0
A43: Undergrade | B43: =SUM(B47:B50) -> 0.012 | C43: =SUM(C47:C50) -> 0.019 | D43: =SUM(D47:D50) -> 0.015 | E43: =SUM(E47:E50) -> 0.02
...

Sheet Procedures
A1: Procedure Information for Tabs
A3: Please save the completed workbook by each week number,year_grading station, I.e. Week 39, 2019_Hilly Acres Farm Ltd.
A5: Producer Number
A6: This tab is for information only.
A7: The information is used in the dropdowns on the pallet information tab.
A9: Hilly Acres Farm Ltd. (Weekly Summary Report)
A10: The reporting under this tab replaces the previous combined weekly marketing reports.
A11: You will note the reporting must be entered separately for each laying facility (barn).
A12: Enter the week # and week ending date in the yellow highlighted area.
A13: Enter the total weekly egg production in dozens from each laying facility (barn) in the green highlighted area
A14: Enter the weekly bird inventory number(s) for each laying facility in the orange highlighted area,
A15: Enter the individual grade out (by dozens and size) for each laying facility in the blue highlighted area.
... A39: 3. Complete the remaining yellow highlighted sections.

Sheet Producer Number
A1: Producer Number | B1: Producer Name
A2: 7168-E7 | B2: Chris Eyking New Barn 7 - Enriched
A3: 7168-E11 | B3: Chris Eyking Barn 11 - Enriched
A4: 7169-C3 | B4: Chris Eyking Barn 3 - Conventional
A5: 7169-E6 | B5: Theodore & John Eyking Sr. Barn 6 - Enriched
A6: Graded IP | B6: Graded IP
A8: Grades
A9: X L
A10: LARGE
A11: MED
A12: SMALL
A15: Packaging
A16: NEW | B16: Packaging weight - 203 (new pallet)
A17: OLD | B17: Packaging weight- 192 (old pallet)
