Workbook

Sheet Mon
A1: Ship Date: | C1: =DATE(2024,1,1)+(B2-1)*7 -> 45516 | G1: BBD | H1: =C1+42-1 -> 45557 | K1: NORTHSIDE
A2: Week | B2: 33
A4: 4. Sobeys - North Sydney | D4: 6.Superstore - North Sydney | G4: 7. WalMart - North Sydney
A5: 1 | B5: OC Xlg | D5: 1 | E5: Lob Xlg | G5: 4 | H5: Wal GV Xlrg
A6: 5 | B6: OC Lg | D6: 10 | E6: Lob Lg | G6: 6 | H6: Wal GV Lg
A7: 0 | B7: OC Med | D7: 0 | E7: Lob br | G7: 0 | H7: Wal Nova Xlg Brn
A8: 1 | B8: OC Br | D8: 7 | E8: Lob 30 Lg | G8: 2 | H8: Wal Nova Brn
A9: 15 | B9: OC 30 Lrg | D9: 6 | E9: ED Jumbo | G9: 0 | H9: Nova Jumbo
A10: 6 | B10: ED Jum | D10: 20 | E10: ED 18 XL | G10: 8 | H10: Wal Nova 18's Lg
A11: 0 | B11: ED 18 XL | D11: =SUM(D5:D10) -> 44 | E11: Box Total | G11: 0 | H11: All Grain Nova
A12: 5 | B12: ED 18 LG | G12: 0 | H12: Nova 6 Pack
A13: 0 | B13: Eyk Lg | D13: PO# | E13: 4869900419 | G13: 4 | H13: XLrg 30 pack Nova
A14: 0 | B14: OC Lg Cozy Coop | G14: 6 | H14: Lrg 30 pack Nova
A15: 1 | B15: OC Org F.Rng (B) | D15: 9. Shoppers - North Sydney | G15: =SUM(G5:G14) -> 30 | H15: Box Total
A16: 1 | B16: OC Lg Free Run (W) | D16: 24 | E16: Lob Lrg
A17: 1 | B17: OC Om3 Free Run (W) | D17: 1 | E17: Lob br | G17: PO# | H17: 8532
A18: 1 | B18: MP Om3 6pk (W) | D18: 1 | E18: MP Om 12pk (W)
A19: 1 | B19: MP Om3 12pk (W) | D19: =SUM(D16:D18) -> 26 | E19: Box Total
A20: 1 | B20: MP Free Run (B)
A21: 0 | B21: MP Coldspring F.Rng (B) | D21: 1. Harbour View | G21: 8. Northside Guest Home
A22: =SUM(A5:A21) -> 39 | B22: Box Total | D22: 0 | E22: Lg Loose | G22: 4 | H22: Lg Loose
D24: 2. Miners Manor | G24: 16. Sexton's Pharmasave
A25: 5.Foodland - Sydney Mines | D25: 3 | E25: Lg Loose | G25: 2 | H25: Eyk Lg
A26: 0 | B26: OC xlg
A27: 0 | B27: OC lrg | D27: 3. Northside General
A28: 0 | B28: OC Med | D28: 4 | E28: Med Loose
A29: 0 | B29: OC Br | G29: **Small Stops**
A30: 0 | B30: ED Jum | G30: =D22+D25+G22 -> 7 | H30: Lg Loose
A31: 0 | B31: ED 18 XL | G31: =D28 -> 4 | H31: Med Loose
A32: 0 | B32: ED 18 LG | G32: =G25 -> 2 | H32: Eyk Lg
A33: =SUM(A26:A32) -> 0 | B33: Box Total
A34: Ship Date: | C34: =C1 -> 45516 | G34: BBD | H34: =H1 -> 45557 | K34: SYDNEY
A36: 10. Sobeys - Syd. River | D36: 11. WalMart - Syd. River | G36: 15. WalMart - Spar Rd.
A37: 2 | B37: OC Xlg | D37: 2 | E37: Wal GV Xlrg | G37: 10 | H37: Wal GV Xlrg
A38: 10 | B38: OC Lg | D38: 12 | E38: Wal GV Lg | G38: 15 | H38: Wal GV Lg
A39: 1 | B39: OC Med | D39: 0 | E39: Wal Nova Xlg Brn | G39: 0 | H39: Wal Nova Xlg Brn
A40: 1 | B40: OC Br | D40: 0 | E40: Wal Nova Brn | G40: 1 | H40: Wal Nova Brn
A41: 12 | B41: OC 30 Lrg | D41: 0 | E41: Nova Jumbo | G41: 1 | H41: Nova Jumbo
A42: 3 | B42: ED Jum | D42: 12 | E42: Wal Nova 18's Lg | G42: 15 | H42: Wal Nova 18's Lg
A43: 24 | B43: ED 18 XL | D43: 0 | E43: All Grain Nova | G43: 1 | H43: All Grain Nova
...

Sheet Tues
A1: Ship Date: | C1: =DATE(2024,1,1)+(Mon!B2-1)*7+1 -> 45517 | G1: BBD | H1: =Mon!C1+42-1 -> 45557
A3: 2. Sobeys - Prince Street | D3: 7. Sobeys - New Waterford | G3: 12. Sobeys - Glace Bay | J3: 9. Foodland - Glace Bay
A4: 2 | B4: OC Xlg | D4: 0 | E4: OC Xlg | G4: 0 | H4: OC Xlg | J4: 1 | K4: OC Xlg
A5: 12 | B5: OC Lg | D5: 4 | E5: OC Lg | G5: 0 | H5: OC Lg | J5: 0 | K5: OC Lg
A6: 1 | B6: OC Med | D6: 1 | E6: OC Med | G6: 0 | H6: OC Med | J6: 0 | K6: OC Med
A7: 2 | B7: OC Br | D7: 0 | E7: OC Br | G7: 0 | H7: OC Br | J7: 0 | K7: OC Br
A8: 20 | B8: OC 30 Lrg | D8: 20 | E8: OC 30 Lrg | G8: 24 | H8: OC 30 Lrg | J8: 5 | K8: OC 30 Lrg
A9: 10 | B9: ED Jum | D9: 2 | E9: ED Jum | G9: 6 | H9: ED Jum | J9: 4 | K9: ED Jum
A10: 6 | B10: ED 18 XL | D10: 2 | E10: ED 18 XL | G10: 7 | H10: ED 18 XL | J10: 4 | K10: ED 18 XL
A11: 0 | B11: ED 18 LG | D11: 0 | E11: ED 18 LG | G11: 0 | H11: ED 18 LG | J11: 0 | K11: ED 18 LG
A12: 2 | B12: Eyk Lg | D12: 0 | E12: Eyk Lg | G12: 2 | H12: Eyk Lg | J12: 0 | K12: Eyk Lg
A13: 0 | B13: OC Lg Cozy Coop | D13: 1 | E13: OC Lg Cozy Coop | G13: 0 | H13: OC Lg Cozy Coop | J13: =SUM(J4:J12) -> 14 | K13: Box Total
A14: 1 | B14: OC Org F.Rng (B) | D14: 0 | E14: OC Org F.Rng (B) | G14: 0 | H14: OC Org F.Rng (B)
A15: 1 | B15: OC Lg Free Run (W) | D15: 1 | E15: OC Lg Free Run (W) | G15: 1 | H15: OC Lg Free Run (W)
A16: 1 | B16: OC Om3 Free Run (W) | D16: 1 | E16: OC Om3 Free Run (W) | G16: 1 | H16: OC Om3 Free Run (W) | J16: 6. Pier Pharmasave
A17: 1 | B17: MP Om3 6pk (W) | D17: 0 | E17: MP Om3 6pk (W) | G17: 1 | H17: MP Om3 6pk (W) | J17: 5 | K17: Eyk Lg
A18: 1 | B18: MP Om3 12pk (W) | D18: 0 | E18: MP Om3 12pk (W) | G18: 0 | H18: MP Om3 12pk (W)
A19: 1 | B19: MP Free Run (B) | D19: 1 | E19: MP Free Run (B) | G19: 0 | H19: MP Free Run (B) | J19: 8. Dominion Pharmasave
A20: 1 | B20: MP Coldspring F.Rng (B) | D20: 1 | E20: MP Coldspring F.Rng (B) | G20: 0 | H20: MP Coldspring F.Rng (B) | J20: 5 | K20: Eyk Lg
A21: =SUM(A4:A20) -> 62 | B21: Box Total | D21: =SUM(D4:D20) -> 34 | E21: Box Total | G21: =SUM(G4:G20) -> 42 | H21: Box Total
J23: 16. Meadows Pharmasave
A24: 5.Superstore - Syd. River | D24: 13.Superstore - Glace Bay | G24: 10. Shoppers - Glace Bay | J24: 15 | K24: Eyk Lg
A25: 3 | B25: Lob Xlg | D25: 2 | E25: Lob Xlg | G25: 10 | H25: Lob Lrg
A26: 0 | B26: Lob Lg | D26: 8 | E26: Lob Lg | G26: 0 | H26: Lob br | J26: 11. Medical Hall Pharmasave
A27: 2 | B27: Lob br | D27: 1 | E27: Lob br | G27: 0 | H27: MP Om 12pk (W) | J27: 20 | K27: Eyk Lg
A28: 6 | B28: Lob 30 Lg | D28: 8 | E28: Lob 30 Lg | G28: =SUM(G25:G27) -> 10 | H28: Box Total | J28: 2 | K28: Eyk Brn
A29: 12 | B29: ED Jumbo | D29: 2 | E29: ED Jumbo
A30: 0 | B30: ED XL 18 | D30: 10 | E30: ED XL 18 | G30: 4. McIllvary Guest Home | J30: **Pharmasave Total**
A31: =SUM(A25:A30) -> 23 | B31: Box Total | D31: =SUM(D25:D30) -> 31 | E31: Box Total | G31: 2 | H31: Lg Loose | J31: =J17+J20+J24+J27 -> 45 | K31: Eyk Lg
A33: PO# | B33: 4869946328 | D33: PO# | E33: 4869950047 | G33: 14. Master Meats
G34: 4 | H34: Eyk Xlg
A35: 1. Giant Tiger | D35: 3. TRA | G35: 4 | H35: Eyk Br
A36: 8 | B36: Eyk Lrg | D36: 12 | E36: Eyk Lg | G36: =SUM(G34:G35) -> 8 | H36: Box Total
A37: 1 | B37: Eyk Br | D37: 8 | E37: OC 30 Lg
A38: 6 | B38: ED 18 XL | D38: =SUM(D36:D37) -> 20 | E38: Box Total | G38: 15. Loaves and Fishes
A39: =SUM(A36:A38) -> 15 | B39: Box Total | G39: 2 | H39: Lg Loose
A40: DAILY TOTALS
A42: Our Compliments | C42: pcs | D42: Walmart | G42: Loblaws | J42: Eyking
A43: =A4+G4+J4+D4 -> 3 | B43: OC Xlg | C43: =D43*15 -> 0 | E43: Wal GV Xlrg | G43: =A25+D25 -> 5 | H43: Lob Xlg | J43: =A9+A29+G9+J9+D9+D29 -> 36 | K43: ED Jum
A44: =A5+G5+J5+D5 -> 16 | B44: OC Lg | C44: =D44*15 -> 0 | E44: Wal GV Lg | G44: =A26+D26+G25 -> 18 | H44: Lob Lg | J44: =A10+A30+G10+J10+D10+D30+A38 -> 35 | K44: ED 18 XL
...

Sheet Wed
A1: Ship Date: | C1: =DATE(2024,1,1)+(Mon!B2-1)*7+2 -> 45518 | G1: BBD | H1: =Mon!C1+49-1 -> 45564 | J1: 21. Cheticamp Co-op
J2: 3 | K2: OC Xlg
A3: 1. Cedar House | D3: 3. Victoria Farmers - Co-op | G3: 14. Port Hood Co-op | J3: 8 | K3: OC Lg
A4: 4 | B4: Lg Loose | D4: 2 | E4: OC Xlg | G4: 2 | H4: OC Xlg | J4: 10 | K4: Eyk Br
D5: 13 | E5: OC Lg | G5: 10 | H5: OC Lg | J5: 12 | K5: OC 30 Lrg
A6: 2. Alderwood Rest Home | D6: 4 | E6: OC Br | G6: 2 | H6: OC Br | J6: 6 | K6: ED Jumbo
A7: 3 | B7: Lg Loose | D7: 8 | E7: ED Jum | G7: 15 | H7: OC 30 Lrg | J7: 8 | K7: Eyk Xlg
D8: 22 | E8: ED 18 XL | G8: =SUM(G4:G7) -> 29 | H8: Box Total | J8: 8 | K8: Eyk Lg
A9: 4. Julia's Bakery | D9: =SUM(D4:D8) -> 49 | E9: Box Total | J9: 12 | K9: ED XL 18
A10: 3 | B10: Lg Loose | J10: 0 | K10: MP Om3 6pk (W)
D11: 11. Whycocomagh Co-op | G11: 16. Shean Co-op | J11: 0 | K11: MP Om3 12pk (W)
A12: 5. Telegraph House | D12: 0 | E12: OC Xlg | G12: 9 | H12: OC Xlg | J12: =SUM(J2:J11) -> 67 | K12: Box Total
A13: 1 | B13: Lg Loose | D13: 12 | E13: OC Lg | G13: 12 | H13: OC Lg
D14: 2 | E14: OC Br | G14: 6 | H14: OC Br | J14: 24. Margaree Co-op
A15: 6. Bean There Café | D15: 12 | E15: OC 30 Lrg | G15: 15 | H15: OC 30 Lrg | J15: 0 | K15: OC Xlg
A16: 1 | B16: Med Loose | D16: 6 | E16: ED Jum | G16: 0 | H16: MP Om3 6pk (W) | J16: 8 | K16: OC Lg
D17: 5 | E17: ED 18 XL | G17: 0 | H17: MP Om3 12pk (W) | J17: 4 | K17: OC Br
A18: 7. Gisele's Inn | D18: =SUM(D12:D17) -> 37 | E18: Box Total | G18: =SUM(G12:G17) -> 42 | H18: Box Total | J18: 0 | K18: OC 30 Lrg
A19: 0 | B19: Lg Loose | J19: 6 | K19: ED Jumbo
J20: 12 | K20: ED XL 18
A21: 8. From Billy Bistro & Pub | D21: 12. Mabou Freshmart | G21: 15. Coal Miners Café | J21: =SUM(J15:J20) -> 30 | K21: Box Total
A22: 0 | B22: Med Loose | D22: 6 | E22: Eyk Xlg | G22: 2 | H22: Lg Loose
D23: 12 | E23: Eyk Lg | J23: 23. Lemoines Co-op
A24: 9. Farmers Daughter | D24: 4 | E24: Eyk Br | G24: 17. Inverness Pantry | J24: 2 | K24: Eyk Xlg
A25: 3 | B25: Eyk Lg | D25: 0 | E25: Lg Loose | G25: 0 | H25: Eyk Lg | J25: 2 | K25: Eyk Lg
A26: 2 | B26: Lg Loose | D26: 0 | E26: OC 30 Lrg | G26: 0 | H26: Lg Loose | J26: 2 | K26: Eyk Br
A27: =SUM(A25:A26) -> 5 | B27: Box Total | D27: 0 | E27: MP Om3 6pk (W) | G27: =SUM(G25:G26) -> 0 | H27: Box Total | J27: =SUM(J24:J26) -> 6 | K27: Box Total
D28: 0 | E28: MP Om3 12pk (W)
A29: 10. McKeigans Pharmacy | D29: =SUM(D22:D28) -> 22 | E29: Box Total | G29: 18. Lawrence's Store | J29: 22. LeBlancs General Store
A30: 3 | B30: Eyk Xlg | G30: 1 | H30: Eyk Lg | J30: 2 | K30: Eyk Xlg
A31: 3 | B31: Lg Eyk | D31: 13. Cabot Trail Food | J31: 2 | K31: Eyk Lg
A32: =SUM(A30:A31) -> 6 | B32: Box Total | D32: 0 | E32: Eyk Xlg | G32: 19. Duck Cove Inn | J32: 0 | K32: Eyk Br
D33: 0 | E33: Eyk Lg | G33: 2 | H33: Lg Loose | J33: =SUM(J30:J32) -> 4 | K33: Box Total
D34: 0 | E34: Eyk Br
D35: =SUM(D32:D34) -> 0 | E35: Box Total | G35: 20. Doucette's Inn | J35: 25. Stone's Drug Store
G36: 2 | H36: Med Loose | J36: 1 | K36: Eyk Lg
J37: 1 | K37: Eyk Br
J38: =SUM(J36:J37) -> 2 | K38: Box Total
A39: DAILY TOTALS
A41: Our Compliments | C41: pcs | D41: Walmart | G41: Loblaws | J41: Eyking
...

Sheet Thurs
A1: Ship Date: | C1: =DATE(2024,1,1)+(Mon!B2-1)*7+3 -> 45519 | G1: BBD | H1: =Mon!C1+49-1 -> 45564 | K1: NORTHSIDE
A3: 1. Sobeys - North Sydney | D3: 3. Foodland - Sydney Mines | G3: 4. Superstore - North Sydney | J3: 5. WalMart - North Sydney
A4: 1 | B4: OC Xlg | D4: 0 | E4: OC xlg | G4: 1 | H4: Lob Xlg | J4: 6 | K4: Wal GV Xlrg
A5: 5 | B5: OC Lg | D5: 8 | E5: OC lrg | G5: 10 | H5: Lob Lg | J5: 6 | K5: Wal GV Lg
A6: 0 | B6: OC Med | D6: 0 | E6: OC Med | G6: 2 | H6: Lob br | J6: 0 | K6: Wal Nova Xlg Brn
A7: 1 | B7: OC Br | D7: 0 | E7: OC Br | G7: 7 | H7: Lob 30 Lg | J7: 1 | K7: Wal Nova Brn
A8: 12 | B8: OC 30 Lrg | D8: 4 | E8: ED Jum | G8: 15 | H8: ED 18 XL | J8: 0 | K8: Nova Jumbo
A9: 8 | B9: ED Jum | D9: 6 | E9: ED 18 XL | G9: 6 | H9: ED Jumbo | J9: 8 | K9: Wal Nova 18's Lg
A10: 5 | B10: ED 18 XL | D10: 0 | E10: ED 18 LG | G10: =SUM(G4:G9) -> 41 | H10: Box Total | J10: 0 | K10: All Grain Nova
A11: 6 | B11: ED 18 LG | D11: =SUM(D4:D10) -> 18 | E11: Box Total | J11: 0 | K11: Nova 6 Pack
A12: 0 | B12: Eyk Lg | G12: PO# | H12: 4869997151 | J12: 0 | K12: XLrg 30 pack Nova
A13: 0 | B13: OC Lg Cozy Coop | J13: 0 | K13: Lrg 30 pack Nova
A14: 0 | B14: OC Org F.Rng (B) | G14: 7. Shoppers - North Sydney | J14: =SUM(J4:J13) -> 21 | K14: Box Total
A15: 0 | B15: OC Lg Free Run (W) | G15: 24 | H15: Lob Lrg
A16: 0 | B16: OC Om3 Free Run (W) | G16: 0 | H16: Lob br | J16: PO# | K16: 8636
A17: 1 | B17: MP Om3 6pk (W) | G17: 0 | H17: MP Om3 12pk (W)
A18: 0 | B18: MP Om3 12pk (W) | G18: =SUM(G15:G17) -> 24 | H18: Box Total
A19: 0 | B19: MP Free Run (B)
A20: 0 | B20: MP Coldspring F.Rng (B)
A21: =SUM(A4:A20) -> 39 | B21: Box Total
A24: 2. Nala's | D24: 15. Janes
A25: 1 | B25: Lg Loose | D25: 1 | E25: Lg Loose
A27: 6. Bonnar's Meats | D27: 16. Bras D'or View
A28: 10 | B28: Eyk Xlg | D28: 3 | E28: Lg Loose
A35: Ship Date: | C35: =C1 -> 45519 | G35: BBD | H35: =H1 -> 45564 | K35: SYDNEY
A37: 8. Sobeys - Syd. River | D37: 12.Colbourne - No Frills | G37: 9. WalMart - Syd. River | J37: 13. WalMart - Spar Rd.
A38: 1 | B38: OC Xlg | D38: 1 | E38: Lob xlg | G38: 4 | H38: Wal GV Xlrg | J38: 15 | K38: Wal GV Xlrg
A39: 6 | B39: OC Lg | D39: 19 | E39: Lob lg | G39: 12 | H39: Wal GV Lg | J39: 20 | K39: Wal GV Lg
A40: 1 | B40: OC Med | D40: 2 | E40: Lob Br | G40: 0 | H40: Wal Nova Xlg Brn | J40: 0 | K40: Wal Nova Xlg Brn
A41: 0 | B41: OC Br | D41: 16 | E41: Lob 30 Lg | G41: 1 | H41: Wal Nova Brn | J41: 1 | K41: Wal Nova Brn
A42: 10 | B42: OC 30 Lrg | D42: 16 | E42: ED18 XL | G42: 0 | H42: Nova Jumbo | J42: 1 | K42: Nova Jumbo
A43: 4 | B43: ED Jum | D43: 6 | E43: ED Jum | G43: 12 | H43: Wal Nova 18's Lg | J43: 20 | K43: Wal Nova 18's Lg
A44: 24 | B44: ED 18 XL | D44: =SUM(D38:D43) -> 60 | E44: Box Total | G44: 0 | H44: All Grain Nova | J44: 1 | K44: All Grain Nova
A45: 0 | B45: ED 18 LG | G45: 0 | H45: Nova 6 Pack | J45: 0 | K45: Nova 6 Pack
A46: 4 | B46: Eyk Lg | D46: PO# | E46: 4869984332 | G46: 0 | H46: XLrg 30 pack Nova | J46: 0 | K46: XLrg 30 pack Nova
A47: 1 | B47: OC Lg Cozy Coop | G47: 12 | H47: Lrg 30 pack Nova | J47: 45 | K47: Lrg 30 pack Nova
A48: 0 | B48: OC Org F.Rng (B) | G48: =SUM(G38:G47) -> 41 | H48: Box Total | J48: =SUM(J38:J47) -> 103 | K48: Box Total
A49: 1 | B49: OC Lg Free Run (W) | D49: 11. Shoppers - Prince St.
A50: 0 | B50: OC Om Free Run (W) | D50: 40 | E50: Lob Lrg | G50: PO# | H50: 1881 | J50: PO# | K50: 7501
A51: 0 | B51: MP Om 6pk (W) | D51: 0 | E51: Lob br
...

Sheet Fri
A1: Ship Date: | C1: =DATE(2024,1,1)+(Mon!B2-1)*7+4 -> 45520 | G1: BBD | H1: =Mon!C1+49-1 -> 45564
A3: 2. Sobeys - Prince Street | D3: 8. Sobeys - New Waterford | G3: 15. Sobeys - Glace Bay | J3: 12. Foodland - Glace Bay | M3: 17. Eskasoni
A4: 1 | B4: OC Xlg | D4: 3 | E4: OC Xlg | G4: 1 | H4: OC Xlg | J4: 0 | K4: OC Xlg | M4: 0 | N4: OC Xlg
A5: 24 | B5: OC Lg | D5: 10 | E5: OC Lg | G5: 12 | H5: OC Lg | J5: 8 | K5: OC Lg | M5: 0 | N5: OC Lg
A6: 1 | B6: OC Med | D6: 0 | E6: OC Med | G6: 0 | H6: OC Med | J6: 1 | K6: OC Med | M6: 0 | N6: OC Med
A7: 2 | B7: OC Br | D7: 2 | E7: OC Br | G7: 1 | H7: OC Br | J7: 0 | K7: OC Br | M7: 0 | N7: OC Br
A8: 60 | B8: OC 30 Lrg | D8: 20 | E8: OC 30 Lrg | G8: 40 | H8: OC 30 Lrg | J8: 10 | K8: OC 30 Lrg | M8: 0 | N8: OC 30 Lrg
A9: 9 | B9: ED Jum | D9: 8 | E9: ED Jum | G9: 5 | H9: ED Jum | J9: 1 | K9: ED Jum | M9: 0 | N9: ED Jum
A10: 12 | B10: ED 18 XL | D10: 3 | E10: ED 18 XL | G10: 4 | H10: ED 18 XL | J10: 0 | K10: ED 18 XL | M10: 0 | N10: ED 18 XL
A11: 7 | B11: ED 18 LG | D11: 0 | E11: ED 18 LG | G11: 6 | H11: ED 18 LG | J11: 0 | K11: OC Org F.rng | M11: 0 | N11: ED 18 LG
A12: 4 | B12: Eyk Lg | D12: 0 | E12: Eyk Lg | G12: 3 | H12: Eyk Lg | J12: 2 | K12: MP Om3 12pk | M12: 0 | N12: MP Om 12
A13: 0 | B13: OC Lg Cozy Coop | D13: 0 | E13: OC Lg Cozy Coop | G13: 0 | H13: OC Lg Cozy Coop | J13: =SUM(J4:J12) -> 22 | K13: Box Total | M13: 0 | N13: Box Total
A14: 0 | B14: OC Org F.Rng (B) | D14: 0 | E14: OC Org F.Rng (B) | G14: 0 | H14: OC Org F.Rng (B)
A15: 1 | B15: OC Lg Free Run (W) | D15: 0 | E15: OC Lg Free Run (W) | G15: 0 | H15: OC Lg Free Run (W)
A16: 0 | B16: OC Om3 Free Run (W) | D16: 0 | E16: OC Om3 Free Run (W) | G16: 0 | H16: OC Om3 Free Run (W) | J16: 6. Pier Pharmasave
A17: 1 | B17: MP Om3 6pk (W) | D17: 0 | E17: MP Om3 6pk (W) | G17: 0 | H17: MP Om3 6pk (W) | J17: 0 | K17: Eyk Lg
A18: 2 | B18: MP Om3 12pk (W) | D18: 1 | E18: MP Om3 12pk (W) | G18: 1 | H18: MP Om3 12pk (W)
A19: 1 | B19: MP Free Run (B) | D19: 1 | E19: MP Free Run (B) | G19: 0 | H19: MP Free Run (B) | J19: 9. Midtown Pharmasave
A20: 1 | B20: MP Coldspring | D20: 0 | E20: MP Coldspring | G20: 0 | H20: MP Coldspring | J20: 0 | K20: Eyk Lg
A21: =SUM(A4:A20) -> 126 | B21: Box Total | D21: =SUM(D4:D20) -> 48 | E21: Box Total | G21: =SUM(G4:G20) -> 73 | H21: Box Total
J22: 10. Dominion Pharmasave
A23: 5.Superstore - Syd. River | D23: 16. Superstore - Glace Bay | G23: 13. Shoppers - Glace Bay | J23: 5 | K23: Eyk Lg
A24: 0 | B24: Lob Xlg | D24: 2 | E24: Lob Xlg | G24: 5 | H24: Lob Lrg
A25: 0 | B25: Lob Lg | D25: 7 | E25: Lob Lg | G25: 0 | H25: Lob br | J25: 14. Medical Hall Pharm.
A26: 1 | B26: Lob br | D26: 2 | E26: Lob br | G26: 0 | H26: MP Om3 12pk (W) | J26: 16 | K26: Eyk Lg
A27: 10 | B27: Lob 30 Lg | D27: 6 | E27: Lob 30 Lg | G27: =SUM(G24:G26) -> 5 | H27: Box Total
A28: 24 | B28: ED 18 XL | D28: 6 | E28: ED 18 XL | J28: 18. Meadows Pharmasave
A29: 0 | B29: ED Jumbo | D29: 4 | E29: ED Jumbo | J29: 15 | K29: Eyk Lg
A30: =SUM(A24:A29) -> 35 | B30: Box Total | D30: =SUM(D24:D29) -> 27 | E30: Box Total
J31: **Pharmasave Total**
A32: PO# | B32: 48670019546 | D32: PO# | E32: 48670020022 | J32: =J17+J20+J23+J26+J29 -> 36 | K32: Eyk Lg
A34: 1. Giant Tiger | D34: 3. Mira Ferry Market | G34: 7. Omni Foods | J34: 11. Seaview Manor
A35: 8 | B35: Eyk Lrg | D35: 0 | E35: Lg Loose | G35: 0 | H35: Eyk Lg | J35: 5 | K35: Med Loose
A36: 1 | B36: Eyk Br | G36: 0 | H36: Lg Loose
A37: 8 | B37: ED 18 XL | D37: 4. TRA | G37: =SUM(G35:G36) -> 0 | H37: Box Total
A38: =SUM(A35:A37) -> 17 | B38: Box Total | D38: 15 | E38: Eyk Lg
D39: 8 | E39: OC 30 Lg
A40: DAILY TOTALS | F40: =SUM(D38:D39) -> 23 | G40: Box Total
A42: Our Compliments | C42: pcs | D42: Walmart | G42: Loblaws | J42: Eyking
A43: =A4+D4+J4+G4+M4 -> 5 | B43: OC Xlg | C43: =D43*15 -> 0 | E43: Wal GV Xlrg | G43: =A24+D24 -> 2 | H43: Lob Xlg | J43: =A9+D9+A29+J9+D29+G9+M9 -> 27 | K43: ED Jum
...

Sheet NFLD
A1: Ship Week: | C1: =Mon!B2+1 -> 34 | F1: BBD | G1: =Mon!C1+49-1 -> 45564
A4: Pallets | B4: Atlantic Grocery | E4: Pallets | F4: Fowlows | I4: Pallets | J4: Focenco
A5: =B5/48 -> 1 | B5: 48 | C5: Eyk Xlg | E5: =F5/48 -> 0 | G5: Eyk Xlg | I5: =J5/48 -> 1 | J5: 48 | K5: Eyk Xlg
A6: =B6/48 -> 7 | B6: 336 | C6: Eyk Lg | E6: =F6/48 -> 0.5 | F6: 24 | G6: Eyk Lg | I6: =J6/48 -> 5 | J6: 240 | K6: Eyk Lg
A7: =B7/48 -> 0 | C7: Eyk Br | E7: =F7/48 -> 0 | G7: Eyk Br | I7: =J7/48 -> 2 | J7: 96 | K7: Eyk Br
A8: =B8/48 -> 0 | C8: ED Jum | E8: =F8/48 -> 0 | G8: ED Jum | I8: =J8/48 -> 0 | K8: ED Jum
A9: =B9/48 -> 0 | C9: ED XL 18 | E9: =F9/48 -> 0 | G9: ED XL 18 | I9: =J9/48 -> 3 | J9: 144 | K9: ED XL 18
A10: =B10/48 -> 3 | B10: 144 | C10: Lg Loose | E10: =F10/48 -> 0.5 | F10: 24 | G10: Lg Loose | I10: =J10/48 -> 0 | K10: Lg Loose
A11: =B11/48 -> 2 | B11: 96 | C11: Med Loose | E11: =F11/48 -> 0 | G11: Med Loose | I11: =J11/48 -> 0 | K11: Med Loose
A12: =B12/48 -> 13 | B12: =SUM(B5:B11) -> 624 | C12: Box Total | E12: =F12/48 -> 1 | F12: =SUM(F5:F11) -> 48 | G12: Box Total | I12: =J12/48 -> 11 | J12: =SUM(J5:J11) -> 528 | K12: Box Total
A40: DAILY TOTALS
A42: Our Compliments | C42: pcs | D42: Walmart | G42: Loblaws | J42: Eyking
B43: OC Xlg | C43: =D43*15 -> 0 | E43: Wal GV Xlrg | H43: Lob Xlg | J43: =B8+F8+J8 -> 0 | K43: ED Jum
B44: OC Lg | C44: =D44*15 -> 0 | E44: Wal GV Lg | H44: Lob Lg | J44: =B9+F9+J9 -> 144 | K44: ED 18 XL
B45: OC Med | C45: =D45*15 -> 0 | E45: Wal Nova Xlg Brn | H45: Lob br | K45: ED 18 LG
B46: OC Br | C46: =D46*15 -> 0 | E46: Wal Nova Brn | H46: Lob 30 | J46: =B5+F5+J5 -> 96 | K46: Eyk Xlg
B47: OC 30 Lrg | C47: =D47*12 -> 0 | E47: Nova Jumbo | J47: =B6+F6+J6 -> 600 | K47: Eyk Lg
B48: OC Lg Cozy Coop | C48: =D48*10 -> 0 | E48: Wal Nova 18's Lg | J48: =B7+F7+J7 -> 96 | K48: Eyk Br
C49: =D49*15 -> 0 | E49: All Grain Nova | J49: =B10+F10+J10 -> 168 | K49: Lg Loose
C50: =D50*15 -> 0 | E50: Nova 6 Pack | J50: =B11+F11+J11 -> 96 | K50: Med Loose
C51: =D51*8 -> 0 | E51: XLrg 30 pack Nova
C52: =D52*8 -> 0 | E52: Lrg 30 pack Nova
A57: Specialty | F57: pcs | G57: Small Tally
B58: OC Org F.Rng (B) | F58: =G58*15 -> 0 | G58: =A45 -> 0 | H58: OC Med
B59: OC Lg Free Run (W) | F59: =G59*15 -> 0 | G59: =A48 -> 0 | H59: OC Lg Cozy Coop
B60: OC Om Free Run (W) | F60: =G60*10 -> 0 | G60: =J45 -> 0 | H60: ED 18 LG
B61: MP Om 6pk (W) | F61: =G61*15 -> 0 | G61: =A46 -> 0 | H61: OC Br
B62: MP Om 12pk (W) | F62: =G62*15 -> 0 | G62: =G45 -> 0 | H62: Lob br
B63: MP Free Run (B) | F63: =G63*5 -> 0 | G63: =A47 -> 0 | H63: OC 30 Lg
B64: MP Coldspring F.Rng (B) | F64: =G64*8 -> 0 | G64: =G46 -> 0 | H64: Lob 30 Lg

Sheet Total
A1: Week Prepared: | C1: =Mon!B2 -> 33 | N1: WEEKLY PACKAGING USE | R1: WEEKLY TOTAL EGG SALES
N2: Carton Type | O2: Pcs | P2: Bundles | S2: Jum | T2: Xlg | U2: Lg | V2: Med | W2: Xlg Br | X2: Lg Br
A3: Our Compliments | D3: Walmart | G3: Loblaws | J3: Eyking | N3: ED Jum | O3: =J4*12 -> 1632 | P3: =O3/125 -> 13.056 | R3: Dozens | S3: =12*(D8+J4) -> 1656 | T3: =15*(A4+D4+G4+J7+J5)+20*D12 -> 9470 | U3: =15*(A5+A9+D5+D9+D10+D11+G5+J6+J8+J10)+20*(A8+D13+G7) -> 33370 | V3: =15*(A6+J11) -> 1710 | W3: =15*D6 -> 0 | X3: =15*(A7+D7+G6+J9) -> 2550
A4: =Mon!A70+Tues!A43+Wed!A42+Thurs!A72+Fri!A43+NFLD!A43 -> 29 | B4: OC Xlg | D4: =Mon!D70+Tues!D43+Wed!D42+Thurs!D72+Fri!D43+NFLD!D43 -> 41 | E4: Wal GV Xlrg | G4: =Mon!G70+Tues!G43+Wed!G42+Thurs!G72+Fri!G43+NFLD!G43 -> 11 | H4: Lob Xlg | J4: =Mon!J70+Tues!J43+Wed!J42+Thurs!J72+Fri!J43+NFLD!J43 -> 136 | K4: ED Jum | N4: ED 18 XL | O4: =J5*10 -> 4140 | P4: =O4/130 -> 31.846154 | R4: Stacks | S4: =S3/15 -> 110.4 | T4: =T3/15 -> 631.33333 | U4: =U3/15 -> 2224.6667 | V4: =V3/15 -> 114 | W4: =W3/15 -> 0 | X4: =X3/15 -> 170
A5: =Mon!A71+Tues!A44+Wed!A43+Thurs!A73+Fri!A44+NFLD!A44 -> 175 | B5: OC Lg | D5: =Mon!D71+Tues!D44+Wed!D43+Thurs!D73+Fri!D44+NFLD!D44 -> 71 | E5: Wal GV Lg | G5: =Mon!G71+Tues!G44+Wed!G43+Thurs!G73+Fri!G44+NFLD!G44 -> 232 | H5: Lob Lg | J5: =Mon!J71+Tues!J44+Wed!J43+Thurs!J73+Fri!J44+NFLD!J44 -> 414 | K5: ED 18 XL | N5: ED 18 LG | O5: =J6*10 -> 240 | P5: =O5/130 -> 1.8461538
A6: =Mon!A72+Tues!A45+Wed!A44+Thurs!A74+Fri!A45+NFLD!A45 -> 6 | B6: OC Med | D6: =Mon!D72+Tues!D45+Wed!D44+Thurs!D74+Fri!D45+NFLD!D45 -> 0 | E6: Wal Nova Xlg Brn | G6: =Mon!G72+Tues!G45+Wed!G44+Thurs!G74+Fri!G45+NFLD!G45 -> 13 | H6: Lob br | J6: =Mon!J72+Tues!J45+Wed!J44+Thurs!J74+Fri!J45+NFLD!J45 -> 24 | K6: ED 18 LG | N6: Eyk Xlg | O6: =J7*15 -> 1965 | P6: =O6/150 -> 13.1
A7: =Mon!A73+Tues!A46+Wed!A45+Thurs!A75+Fri!A46+NFLD!A46 -> 42 | B7: OC Br | D7: =Mon!D73+Tues!D46+Wed!D45+Thurs!D75+Fri!D46+NFLD!D46 -> 6 | E7: Wal Nova Brn | G7: =Mon!G73+Tues!G46+Wed!G45+Thurs!G75+Fri!G46+NFLD!G46 -> 80 | H7: Lob 30 | J7: =Mon!J73+Tues!J46+Wed!J45+Thurs!J75+Fri!J46+NFLD!J46 -> 131 | K7: Eyk Xlg | N7: Eyk Lg | O7: =J8*15 -> 11400 | P7: =O7/150 -> 76 | R7: Week | S7: =Mon!B2 -> 33
A8: =Mon!A74+Tues!A47+Wed!A46+Thurs!A76+Fri!A47+NFLD!A47 -> 318 | B8: OC 30 Lrg | D8: =Mon!D74+Tues!D47+Wed!D46+Thurs!D76+Fri!D47+NFLD!D47 -> 2 | E8: Nova Jumbo | J8: =Mon!J74+Tues!J47+Wed!J46+Thurs!J76+Fri!J47+NFLD!J47 -> 760 | K8: Eyk Lg | N8: Eyk Br | O8: =J9*15 -> 1635 | P8: =O8/150 -> 10.9
A9: =Mon!A75+Tues!A48+Wed!A47+Thurs!A77+Fri!A48+NFLD!A48 -> 2 | B9: OC Lg Cozy Coop | D9: =Mon!D75+Tues!D48+Wed!D47+Thurs!D77+Fri!D48+NFLD!D48 -> 75 | E9: Wal Nova 18's Lg | J9: =Mon!J75+Tues!J48+Wed!J47+Thurs!J77+Fri!J48+NFLD!J48 -> 109 | K9: Eyk Br | N9: Filler Flats | O9: =7*(J10+J11)+8*(D12+D13+G7)+5*A9 -> 3761 | P9: =O9/140 -> 26.864286
D10: =Mon!D76+Tues!D49+Wed!D48+Thurs!D78+Fri!D49+NFLD!D49 -> 2 | E10: All Grain Nova | J10: =Mon!J76+Tues!J49+Wed!J48+Thurs!J78+Fri!J49+NFLD!J49 -> 205 | K10: Lg Loose | N10: OC Xlg | O10: =A4*15 -> 435 | P10: =O10/250 -> 1.74
D11: =Mon!D77+Tues!D50+Wed!D49+Thurs!D79+Fri!D50+NFLD!D50 -> 0 | E11: Nova 6 Pack | J11: =Mon!J77+Tues!J50+Wed!J49+Thurs!J79+Fri!J50+NFLD!J50 -> 108 | K11: Med Loose | N11: OC Lg | O11: =A5*15 -> 2625 | P11: =O11/250 -> 10.5
D12: =Mon!D78+Tues!D51+Wed!D50+Thurs!D80+Fri!D51+NFLD!D51 -> 4 | E12: XLrg 30 pack Nova | N12: OC Med | O12: =A6*15 -> 90 | P12: =O12/250 -> 0.36
D13: =Mon!D79+Tues!D52+Wed!D51+Thurs!D81+Fri!D52+NFLD!D52 -> 111 | E13: Lrg 30 pack Nova | N13: OC Br | O13: =A7*15 -> 630 | P13: =O13/250 -> 2.52
N14: OC 30 Lrg Sleeve | O14: =5*A9 -> 10 | P14: =O14/50 -> 0.2
N15: OC Lg Cozy Coop | O15: =15*A9 -> 30 | P15: =O15/250 -> 0.12
A16: Specialty | D16: Small Tally | G16: QTY | H16: Carts | N16: Lob Xlg | O16: =15*G4 -> 165 | P16: =O16/250 -> 0.66
A17: =Mon!A85+Tues!A58+Wed!A57+Thurs!A87+Fri!A58+NFLD!A58 -> 5 | B17: OC Org F.Rng (B) | D17: =A6 -> 6 | E17: OC Med | G17: =Mon!J85+Tues!J58+Thurs!J87+Fri!J58 -> 0 | H17: OC Xlg | N17: Lob Lg | O17: =15*G5 -> 3480 | P17: =O17/250 -> 13.92
A18: =Mon!A86+Tues!A59+Wed!A58+Thurs!A88+Fri!A59+NFLD!A59 -> 8 | B18: OC Lg Free Run (W) | D18: =A9 -> 2 | E18: OC Lg Cozy Coop | G18: =Mon!J86+Tues!J59+Thurs!J88+Fri!J59 -> 1 | H18: OC Lg | N18: Lob br | O18: =15*G6 -> 195 | P18: =O18/250 -> 0.78
A19: =Mon!A87+Tues!A60+Wed!A59+Thurs!A89+Fri!A60+NFLD!A60 -> 6 | B19: OC Om Free Run (W) | D19: =J6 -> 24 | E19: ED 18 LG | G19: =Mon!J87+Tues!J60+Thurs!J89+Fri!J60 -> 8 | H19: OC 30 Lrg | N19: Lob 30 Sleeve | O19: =8*G7 -> 640 | P19: =O19/50 -> 12.8
A20: =Mon!A88+Tues!A61+Wed!A60+Thurs!A90+Fri!A61+NFLD!A61 -> 5 | B20: MP Om 6pk (W) | D20: =A7 -> 42 | E20: OC Br | G20: =Mon!J88+Tues!J61+Thurs!J90+Fri!J61 -> 0 | H20: Lob Xlg | N20: Wal GV Xlrg | O20: =15*D4 -> 615 | P20: =O20/150 -> 4.1
A21: =Mon!A89+Tues!A62+Wed!A61+Thurs!A91+Fri!A62+NFLD!A62 -> 9 | B21: MP Om 12pk (W) | D21: =G6 -> 13 | E21: Lob br | G21: =Mon!J89+Tues!J62+Thurs!J91+Fri!J62 -> 0 | H21: Lob Lg | N21: Wal GV Lg | O21: =15*D5 -> 1065 | P21: =O21/150 -> 7.1
A22: =Mon!A90+Tues!A63+Wed!A62+Thurs!A92+Fri!A63+NFLD!A63 -> 8 | B22: MP Free Run (B) | D22: =A8 -> 318 | E22: OC 30 Lg | G22: =Mon!J90+Tues!J63+Thurs!J92+Fri!J63 -> 0 | H22: Lob 30 Lg | N22: Wal Nova Xlg Brn | O22: =15*D6 -> 0 | P22: =O22/150 -> 0
A23: =Mon!A91+Tues!A64+Wed!A63+Thurs!A93+Fri!A64+NFLD!A64 -> 3 | B23: MP Coldspring F.Rng (B) | D23: =G7 -> 80 | E23: Lob 30 Lg | G23: =Mon!J91+Tues!J64+Thurs!J93+Fri!J64 -> 3 | H23: ED 18 XL | N23: Wal Nova Brn | O23: =15*D7 -> 90 | P23: =O23/150 -> 0.6
G24: =Mon!J92+Tues!J65+Thurs!J94+Fri!J65 -> 0 | H24: ED 18 LG | N24: Nova Jumbo | O24: =12*D8 -> 24 | P24: =O24/125 -> 0.192
N25: Wal Nova 18's Lg | O25: =10*D9 -> 750 | P25: =O25/130 -> 5.7692308
N26: All Grain Nova | O26: =15*D10 -> 30 | P26: =O26/125 -> 0.24
N27: Nova 6 Pack | O27: =15*D11 -> 0 | P27: =O27/125 -> 0
N28: XLrg 30 pack Nova Sleeve | O28: =8*D12 -> 32 | P28: =O28/50 -> 0.64
N29: Lrg 30 pack Nova Sleeve | O29: =8*D13 -> 888 | P29: =O29/50 -> 17.76
N31: Boxe Type | O31: Pcs | P31: Bundles
N32: Blue | O32: =A4+D4+G4+J5+J7-24*(G17+G20+G23) -> 554 | P32: =O32/25-24*(G17+G20+G23) -> -49.84 | R32: *box usage generally accounts for carts, but does not account if stores order a cart + boxes in the same order or if we run out of carts and have to pack carts into boxes
N33: Red | O33: =A5+A8+A9+D5+D10+D11+G5+J6+J8+J10-24*(G18+G21+G24)-20*G19 -> 1605 | P33: =O33/25-24*(G18+G21+G24)-20*G19 -> -119.8
N34: Black | O34: =D8+D9+J4 -> 213 | P34: =O34/25 -> 8.52
N35: Green | O35: =A6+J11 -> 114 | P35: =O35/25 -> 4.56
N36: Brown | O36: =A7+G6+D7+D6+J9 -> 170 | P36: =O36/25 -> 6.8
N37: Nova Wide | O37: =D12+D13 -> 115 | P37: =O37/20 -> 5.75
N38: Lob Wide | O38: =G7-13*G22 -> 80 | P38: =O38/20-13*G22 -> 4
